Workbook

Sheet Read me
A1: AU intakes 9,987 (20 Oct) to 9,391 (26 Oct): course-by-course account of the −596 net change
A2: Prepared 27 Oct 2026 from the live database (project fxcwkweaxjtknorudmwp), read only. Platform Admin mandate 27 Oct 05:46, Priority 1A.
A3: Measure: an AU active course is "admitted" for intakes when it has at least one active catalogue.course_intakes row. Same definition and the same denominator (26,103) on both dates.
A4: Bridge: 9,987 − (868 − x) + (23 + 225 + (24 − x)) = 9,391 for any x from 0 to 24. Net −596 is exact; gross loss is 844–868 and gross gain is 248–272.
A5: x: 24 of the calendar-only courses got their calendar rows on 21 Oct (after the 9,987 snapshot). course_intakes has no insert time or writer column, so they cannot be told apart course by course (a governance gap).
A6: Writer for every loss: one statement of migration 20261022042000_cf247_intakes_page_only (admin_control_events 20396, 22 Oct 11:50:09 UTC: calendar_withdrawn 2,166 rows across countries), carrying out the Platform Admin decision of 22 Oct "Page-only months, no API change".
A7: Reasons tested and found zero: retirement (no AU course retired or created since 18 Oct), re-yearing (no settle job; every active row has intake_year null), reclassification (definition unchanged), identity refusal (no Layer 4 intake items on these courses since 18 Oct), defective write.
A8: Verdict: supersession by a deliberate policy change. No writer defect, so no PR. The withdrawn values are not legitimate under the page-only rule, so nothing is restored through the admission path; they come back only from the course page (AI reader) or by a Platform Admin calendar decision (MARK-FILE).
A9: Like-for-like page-only baseline on 20 Oct: about 9,084 (9,076 + 8). On that basis intakes grew to 9,391 (+307).

Sheet Courses
A1: Group | B1: What happened | C1: Provider | D1: Course | E1: Course id | F1: Withdrawn calendar writer | G1: Withdrawn months | H1: First AI fill | I1: First page evidence
A2: G2 | B2: Gained: new page or adapter intake row (evidence after the 20 Oct snapshot) | C2: Curtin University | D2: Bachelor of Applied Science (Architectural Science) | E2: 6a8abdc6-7de3-4223-be3d-ae89058199a5 | I2: 2026-10-22T08:06:03.991192+00:00
A3: G2 | B3: Gained: new page or adapter intake row (evidence after the 20 Oct snapshot) | C3: Curtin University | D3: Bachelor of Education (Early Childhood Education) | E3: 0ae014d8-454b-4326-80c9-0401a808e1ff | I3: 2026-10-22T08:02:46.668109+00:00
A4: G2 | B4: Gained: new page or adapter intake row (evidence after the 20 Oct snapshot) | C4: Curtin University | D4: Bachelor of Engineering (Civil and Construction Engineering) (Honours), Bachelor of Science (Mining) | E4: d894b2f7-1040-433a-b654-d97c3fc9dfcd | I4: 2026-10-22T08:05:57.502571+00:00
A5: G2 | B5: Gained: new page or adapter intake row (evidence after the 20 Oct snapshot) | C5: Curtin University | D5: Bachelor of Science (Medical Radiation Science) | E5: 8712a3e6-37f9-47fa-97e4-389368358298 | I5: 2026-10-22T07:40:31.233191+00:00
A6: G2 | B6: Gained: new page or adapter intake row (evidence after the 20 Oct snapshot) | C6: Curtin University | D6: Bachelor of Science (Psychology), Bachelor of Commerce (Human Resource Management and Industrial Relations) | E6: bb95a2ff-7800-46dc-b425-2b08d3b15118 | I6: 2026-10-22T08:06:01.661232+00:00
A7: G2 | B7: Gained: new page or adapter intake row (evidence after the 20 Oct snapshot) | C7: Curtin University | D7: Bachelor of Science (Psychology), Bachelor of Commerce (Marketing) | E7: ffa2e6bb-5286-4bdf-98fe-ed6ea586b402 | I7: 2026-10-22T08:06:02.148192+00:00
A8: G2 | B8: Gained: new page or adapter intake row (evidence after the 20 Oct snapshot) | C8: Curtin University | D8: Master of Science (Food Science and Technology) | E8: 48b14365-49bc-410f-9507-0357ae0cc0e7 | I8: 2026-10-22T08:05:57.526357+00:00
A9: G2 | B9: Gained: new page or adapter intake row (evidence after the 20 Oct snapshot) | C9: Griffith University | D9: Master of Cybersecurity | E9: 877a8e63-25d5-4075-90d7-c0b029c17ef9 | I9: 2026-10-23T01:25:30.895957+00:00
A10: G2 | B10: Gained: new page or adapter intake row (evidence after the 20 Oct snapshot) | C10: JMC Academy | D10: Associate Degree of Creative Arts (Music Theatre) | E10: 6992dfd6-054c-4f04-9fdf-e9dd8fc76151 | I10: 2026-10-24T06:05:19.208248+00:00
A11: G2 | B11: Gained: new page or adapter intake row (evidence after the 20 Oct snapshot) | C11: JMC Academy | D11: Bachelor of Creative Arts (Music Theatre) Accelerated | E11: 4131c2c4-d16b-4def-956e-fabdacb9c58e | I11: 2026-10-24T06:05:20.056189+00:00
A12: G2 | B12: Gained: new page or adapter intake row (evidence after the 20 Oct snapshot) | C12: Kaplan Business School Pty Ltd | D12: Graduate Certificate in Generative AI for Business | E12: a6d1b040-16b4-401e-ae56-519f5b95812e | I12: 2026-10-24T14:10:34.439198+00:00
A13: G2 | B13: Gained: new page or adapter intake row (evidence after the 20 Oct snapshot) | C13: Melbourne Polytechnic | D13: Master of Information Technology | E13: 8af3b94b-becc-4e00-82a7-55aeed8d6b7c | I13: 2026-10-23T08:50:36.430192+00:00
... A24: G2 | B24: Gained: new page or adapter intake row (evidence after the 20 Oct snapshot) | C24: University of Technology Sydney (UTS) | D24: Bachelor of Communication (Digital and Social Media) | E24: 8683dd0e-8ab0-4dd4-8754-060bb2d3cde6 | I24: 2026-10-22T12:28:11.97085+00:00
A25: G4 | B25: Lost: calendar-derived intakes withdrawn 22 Oct 11:50 UTC (page-only rule), nothing on the course page replaced them | C25: AAPoly, AMI Education | D25: Advanced Diploma of Hospitality Management | E25: 52e66767-9ae7-4bf9-b0d2-8b392b2c8693 | F25: provider-calendar-defaults (security.calendar_default_intakes_apply_v1) | G25: March
A26: G4 | B26: Lost: calendar-derived intakes withdrawn 22 Oct 11:50 UTC (page-only rule), nothing on the course page replaced them | C26: AAPoly, AMI Education | D26: Bachelor of Business (Cyber Security) | E26: f60ce116-ad75-4357-9845-bc4f954eb141 | F26: provider-calendar-defaults (security.calendar_default_intakes_apply_v1) | G26: March
A27: G4 | B27: Lost: calendar-derived intakes withdrawn 22 Oct 11:50 UTC (page-only rule), nothing on the course page replaced them | C27: AAPoly, AMI Education | D27: Bachelor of Business (Digital Marketing) | E27: 4bb364d3-e8df-48d8-967b-d720903a0ee4 | F27: provider-calendar-defaults (security.calendar_default_intakes_apply_v1) | G27: March
A28: G4 | B28: Lost: calendar-derived intakes withdrawn 22 Oct 11:50 UTC (page-only rule), nothing on the course page replaced them | C28: AAPoly, AMI Education | D28: Bachelor of Business (Leadership and Management) | E28: 6c38020f-d81e-422b-8716-b7771f995ad3 | F28: provider-calendar-defaults (security.calendar_default_intakes_apply_v1) | G28: March
A29: G4 | B29: Lost: calendar-derived intakes withdrawn 22 Oct 11:50 UTC (page-only rule), nothing on the course page replaced them | C29: AAPoly, AMI Education | D29: Bachelor of Information Technology | E29: 5fb408a0-4d7d-48cb-b5dd-c2d41b19377d | F29: provider-calendar-defaults (security.calendar_default_intakes_apply_v1) | G29: March
A30: G4 | B30: Lost: calendar-derived intakes withdrawn 22 Oct 11:50 UTC (page-only rule), nothing on the course page replaced them | C30: AAPoly, AMI Education | D30: Bachelor of Tourism and Hospitality Management | E30: 4b514968-4a30-4389-a8ef-e0b79b62925c | F30: provider-calendar-defaults (security.calendar_default_intakes_apply_v1) | G30: March
A31: G4 | B31: Lost: calendar-derived intakes withdrawn 22 Oct 11:50 UTC (page-only rule), nothing on the course page replaced them | C31: AAPoly, AMI Education | D31: Certificate III in Commercial Cookery | E31: cd7e435c-0ad7-49ee-875d-fccf6fb613ab | F31: provider-calendar-defaults (security.calendar_default_intakes_apply_v1) | G31: March
A32: G4 | B32: Lost: calendar-derived intakes withdrawn 22 Oct 11:50 UTC (page-only rule), nothing on the course page replaced them | C32: AAPoly, AMI Education | D32: Certificate IV in Kitchen Management | E32: fe25cb7d-857d-4fe2-92c5-9265ddf4c193 | F32: provider-calendar-defaults (security.calendar_default_intakes_apply_v1) | G32: March
A33: G4 | B33: Lost: calendar-derived intakes withdrawn 22 Oct 11:50 UTC (page-only rule), nothing on the course page replaced them | C33: AAPoly, AMI Education | D33: Diploma of Hospitality Management | E33: 5a8286f7-c6c3-4d0b-a62e-f549eef2ed41 | F33: provider-calendar-defaults (security.calendar_default_intakes_apply_v1) | G33: March
A34: G4 | B34: Lost: calendar-derived intakes withdrawn 22 Oct 11:50 UTC (page-only rule), nothing on the course page replaced them | C34: AAPoly, AMI Education | D34: Master of Information Technology | E34: 2493488e-3d1e-4591-878a-89bae9d15b0d | F34: provider-calendar-defaults (security.calendar_default_intakes_apply_v1) | G34: March
A35: G4 | B35: Lost: calendar-derived intakes withdrawn 22 Oct 11:50 UTC (page-only rule), nothing on the course page replaced them | C35: Albright Institute of Business and Language; Albright Institute of English | D35: Advanced Diploma of Civil Construction Design | E35: 55e5e1e1-3698-47f2-9039-3203589c4505 | F35: provider-calendar-defaults (security.calendar_default_intakes_apply_v1) | G35: January, March
A36: G4 | B36: Lost: calendar-derived intakes withdrawn 22 Oct 11:50 UTC (page-only rule), nothing on the course page replaced them | C36: Albright Institute of Business and Language; Albright Institute of English | D36: Advanced Diploma of Engineering Technology - Electrical | E36: 59f64049-9309-4366-a00c-45357f66a7db | F36: provider-calendar-defaults (security.calendar_default_intakes_apply_v1) | G36: January, March
... A892: G4 | B892: Lost: calendar-derived intakes withdrawn 22 Oct 11:50 UTC (page-only rule), nothing on the course page replaced them | C892: William Angliss Institute | D892: Certificate III in Patisserie | E892: c041dd8c-fe0f-46b6-929d-0815f4128dc1 | F892: provider-calendar-defaults (security.calendar_default_intakes_apply_v1) | G892: February, July
A893: G5 | B893: Kept: calendar rows withdrawn 22 Oct, refilled from the course page by the AI reader 23–25 Oct | C893: Central Queensland University | D893: Bachelor of Allied Health | E893: e0391228-bc6c-4753-afce-7fce5251a7ce | F893: provider-calendar-defaults (security.calendar_default_intakes_apply_v1) | G893: July, March | H893: 2026-10-23T06:26:29.191015+00:00
A894: G5 | B894: Kept: calendar rows withdrawn 22 Oct, refilled from the course page by the AI reader 23–25 Oct | C894: Central Queensland University | D894: Bachelor of Nursing | E894: a7e44a93-fcb3-4359-a0fe-600c34e8404e | F894: provider-calendar-defaults (security.calendar_default_intakes_apply_v1) | G894: July, March | H894: 2026-10-23T01:09:19.886606+00:00
A895: G5 | B895: Kept: calendar rows withdrawn 22 Oct, refilled from the course page by the AI reader 23–25 Oct | C895: Central Queensland University | D895: Graduate Diploma of International Business | E895: ad400aa4-95e4-4a1d-b3da-c7e132de38a5 | F895: provider-calendar-intakes (security.semester_intake_apply_v1) | G895: July, March | H895: 2026-10-23T01:11:20.730999+00:00
A896: G5 | B896: Kept: calendar rows withdrawn 22 Oct, refilled from the course page by the AI reader 23–25 Oct | C896: Charles Darwin University | D896: Bachelor of Nursing | E896: 90bf1e11-360e-486d-9e63-43d35c77d862 | F896: provider-calendar-defaults (security.calendar_default_intakes_apply_v1) | G896: July, March | H896: 2026-10-23T01:03:28.560711+00:00
A897: G5 | B897: Kept: calendar rows withdrawn 22 Oct, refilled from the course page by the AI reader 23–25 Oct | C897: Charles Sturt University | D897: Bachelor of Veterinary Biology / Bachelor of Veterinary Science | E897: c6f11a32-02b9-4ca8-ad3e-eb91f8fbfbc7 | F897: provider-calendar-defaults (security.calendar_default_intakes_apply_v1) | G897: July, March | H897: 2026-10-23T01:17:22.883169+00:00
A898: G5 | B898: Kept: calendar rows withdrawn 22 Oct, refilled from the course page by the AI reader 23–25 Oct | C898: Curtin University | D898: Bachelor of Medical Sciences (Honours) | E898: 705ec3ce-6569-4cca-bd87-04b7425fa375 | F898: provider-calendar-defaults (security.calendar_default_intakes_apply_v1) | G898: July, May | H898: 2026-10-23T00:55:21.720743+00:00
A899: G5 | B899: Kept: calendar rows withdrawn 22 Oct, refilled from the course page by the AI reader 23–25 Oct | C899: Federation University Australia | D899: Bachelor of Education (Early Childhood Education) | E899: 5dc8bbf4-4f59-497e-9a53-7bf33e458702 | F899: provider-calendar-defaults (security.calendar_default_intakes_apply_v1) | G899: July, March | H899: 2026-10-23T00:50:32.769198+00:00
A900: G5 | B900: Kept: calendar rows withdrawn 22 Oct, refilled from the course page by the AI reader 23–25 Oct | C900: Federation University Australia | D900: Bachelor of Nursing | E900: fc2fee8a-c16f-4b59-baee-9c3a4055dbb8 | F900: provider-calendar-defaults (security.calendar_default_intakes_apply_v1) | G900: July, March | H900: 2026-10-23T06:33:21.263825+00:00
A901: G5 | B901: Kept: calendar rows withdrawn 22 Oct, refilled from the course page by the AI reader 23–25 Oct | C901: Federation University Australia | D901: Bachelor of Nursing | E901: 676aa839-2e8c-44ff-9e4e-82c56a86df53 | F901: provider-calendar-defaults (security.calendar_default_intakes_apply_v1) | G901: July, March | H901: 2026-10-23T00:52:25.922186+00:00
A902: G5 | B902: Kept: calendar rows withdrawn 22 Oct, refilled from the course page by the AI reader 23–25 Oct | C902: Flinders University | D902: Bachelor of Education (Honours) | E902: ffcb9d38-c61e-4d00-a2ea-d9a496308dca | F902: provider-calendar-defaults (security.calendar_default_intakes_apply_v1) | G902: August, March | H902: 2026-10-23T06:34:55.774858+00:00
A903: G5 | B903: Kept: calendar rows withdrawn 22 Oct, refilled from the course page by the AI reader 23–25 Oct | C903: Flinders University | D903: Bachelor of Information Technology (Honours) | E903: 14b91340-13b9-400b-9c43-9761463c32c2 | F903: provider-calendar-defaults (security.calendar_default_intakes_apply_v1) | G903: August, March | H903: 2026-10-26T12:24:24.465684+00:00
A904: G5 | B904: Kept: calendar rows withdrawn 22 Oct, refilled from the course page by the AI reader 23–25 Oct | C904: Flinders University | D904: Bachelor of Information Technology (Honours) | E904: 93a41fe9-1573-4abd-8980-2dc50b8e7358 | F904: provider-calendar-defaults (security.calendar_default_intakes_apply_v1) | G904: August, March | H904: 2026-10-23T01:04:22.949414+00:00
... A951: G5 | B951: Kept: calendar rows withdrawn 22 Oct, refilled from the course page by the AI reader 23–25 Oct | C951: Western Sydney University | D951: Diploma in Design/ Bachelor of Graphic Design (Pathway to Teaching Secondary) | E951: a6779c9a-6c69-47c6-afdb-c44b362ca364 | F951: provider-calendar-defaults (security.calendar_default_intakes_apply_v1) | G951: March | H951: 2026-10-23T01:09:20.058885+00:00
...

Sheet By provider
A1: Provider | B1: Lost (G4) | C1: Kept by AI refill (G5) | D1: Gained page/adapter (G2) | E1: Gained AI reader (G6) | F1: Net
A2: AAPoly, AMI Education | B2: =COUNTIFS(Courses!$C:$C,$A2,Courses!$A:$A,"G4") | C2: =COUNTIFS(Courses!$C:$C,$A2,Courses!$A:$A,"G5") | D2: =COUNTIFS(Courses!$C:$C,$A2,Courses!$A:$A,"G2") | E2: =COUNTIFS(Courses!$C:$C,$A2,Courses!$A:$A,"G6") | F2: =-B2+D2+E2
A3: Adelaide University | B3: =COUNTIFS(Courses!$C:$C,$A3,Courses!$A:$A,"G4") | C3: =COUNTIFS(Courses!$C:$C,$A3,Courses!$A:$A,"G5") | D3: =COUNTIFS(Courses!$C:$C,$A3,Courses!$A:$A,"G2") | E3: =COUNTIFS(Courses!$C:$C,$A3,Courses!$A:$A,"G6") | F3: =-B3+D3+E3
A4: Albright Institute of Business and Language; Albright Institute of English | B4: =COUNTIFS(Courses!$C:$C,$A4,Courses!$A:$A,"G4") | C4: =COUNTIFS(Courses!$C:$C,$A4,Courses!$A:$A,"G5") | D4: =COUNTIFS(Courses!$C:$C,$A4,Courses!$A:$A,"G2") | E4: =COUNTIFS(Courses!$C:$C,$A4,Courses!$A:$A,"G6") | F4: =-B4+D4+E4
A5: Amtech Institute | B5: =COUNTIFS(Courses!$C:$C,$A5,Courses!$A:$A,"G4") | C5: =COUNTIFS(Courses!$C:$C,$A5,Courses!$A:$A,"G5") | D5: =COUNTIFS(Courses!$C:$C,$A5,Courses!$A:$A,"G2") | E5: =COUNTIFS(Courses!$C:$C,$A5,Courses!$A:$A,"G6") | F5: =-B5+D5+E5
A6: Anglican Church Grammar School | B6: =COUNTIFS(Courses!$C:$C,$A6,Courses!$A:$A,"G4") | C6: =COUNTIFS(Courses!$C:$C,$A6,Courses!$A:$A,"G5") | D6: =COUNTIFS(Courses!$C:$C,$A6,Courses!$A:$A,"G2") | E6: =COUNTIFS(Courses!$C:$C,$A6,Courses!$A:$A,"G6") | F6: =-B6+D6+E6
A7: Australian Catholic University | B7: =COUNTIFS(Courses!$C:$C,$A7,Courses!$A:$A,"G4") | C7: =COUNTIFS(Courses!$C:$C,$A7,Courses!$A:$A,"G5") | D7: =COUNTIFS(Courses!$C:$C,$A7,Courses!$A:$A,"G2") | E7: =COUNTIFS(Courses!$C:$C,$A7,Courses!$A:$A,"G6") | F7: =-B7+D7+E7
A8: Australian National University | B8: =COUNTIFS(Courses!$C:$C,$A8,Courses!$A:$A,"G4") | C8: =COUNTIFS(Courses!$C:$C,$A8,Courses!$A:$A,"G5") | D8: =COUNTIFS(Courses!$C:$C,$A8,Courses!$A:$A,"G2") | E8: =COUNTIFS(Courses!$C:$C,$A8,Courses!$A:$A,"G6") | F8: =-B8+D8+E8
A9: Australian Pacific College, Southern Cross High School, English Unlimited Sydney, English Unlimited Melbourne | B9: =COUNTIFS(Courses!$C:$C,$A9,Courses!$A:$A,"G4") | C9: =COUNTIFS(Courses!$C:$C,$A9,Courses!$A:$A,"G5") | D9: =COUNTIFS(Courses!$C:$C,$A9,Courses!$A:$A,"G2") | E9: =COUNTIFS(Courses!$C:$C,$A9,Courses!$A:$A,"G6") | F9: =-B9+D9+E9
A10: Avondale University | B10: =COUNTIFS(Courses!$C:$C,$A10,Courses!$A:$A,"G4") | C10: =COUNTIFS(Courses!$C:$C,$A10,Courses!$A:$A,"G5") | D10: =COUNTIFS(Courses!$C:$C,$A10,Courses!$A:$A,"G2") | E10: =COUNTIFS(Courses!$C:$C,$A10,Courses!$A:$A,"G6") | F10: =-B10+D10+E10
A11: BPP Institute Pty Ltd | B11: =COUNTIFS(Courses!$C:$C,$A11,Courses!$A:$A,"G4") | C11: =COUNTIFS(Courses!$C:$C,$A11,Courses!$A:$A,"G5") | D11: =COUNTIFS(Courses!$C:$C,$A11,Courses!$A:$A,"G2") | E11: =COUNTIFS(Courses!$C:$C,$A11,Courses!$A:$A,"G6") | F11: =-B11+D11+E11
A12: Bond University Limited | B12: =COUNTIFS(Courses!$C:$C,$A12,Courses!$A:$A,"G4") | C12: =COUNTIFS(Courses!$C:$C,$A12,Courses!$A:$A,"G5") | D12: =COUNTIFS(Courses!$C:$C,$A12,Courses!$A:$A,"G2") | E12: =COUNTIFS(Courses!$C:$C,$A12,Courses!$A:$A,"G6") | F12: =-B12+D12+E12
A13: Box Hill Institute | B13: =COUNTIFS(Courses!$C:$C,$A13,Courses!$A:$A,"G4") | C13: =COUNTIFS(Courses!$C:$C,$A13,Courses!$A:$A,"G5") | D13: =COUNTIFS(Courses!$C:$C,$A13,Courses!$A:$A,"G2") | E13: =COUNTIFS(Courses!$C:$C,$A13,Courses!$A:$A,"G6") | F13: =-B13+D13+E13
... A83: William Angliss Institute | B83: =COUNTIFS(Courses!$C:$C,$A83,Courses!$A:$A,"G4") | C83: =COUNTIFS(Courses!$C:$C,$A83,Courses!$A:$A,"G5") | D83: =COUNTIFS(Courses!$C:$C,$A83,Courses!$A:$A,"G2") | E83: =COUNTIFS(Courses!$C:$C,$A83,Courses!$A:$A,"G6") | F83: =-B83+D83+E83
A84: Total | B84: =SUM(B2:B83) | C84: =SUM(C2:C83) | D84: =SUM(D2:D83) | E84: =SUM(E2:E83) | F84: =SUM(F2:F83)
