Workbook

Sheet Read me
A1: Top five Australian universities: source inventories
A3: Prepared | B3: 27 Oct 2026, from the live CourseFinder (StudySearch PIM) database (Supabase project fxcwkweaxjtknorudmwp), read-only queries only. Per-field states come from pipeline.course_attribute_coverage (rebuilt hourly; this copy built 26 Oct 2026 19:47 UTC).
A4: Scope | B4: Active courses at five published providers: The University of Sydney (655), UNSW Sydney (667), Macquarie University (461), Australian National University (423), The University of Melbourne (441). 2,647 courses in all.
A5: What it answers | B5: For each university: which courses are advertised (have an official course page) and which are register-only or have no usable page; the state of the course page and its identity proof; the tuition, intake, English and delivery sources the platform holds, whether they are approved and which study levels they cover; and the entry-requirements sources. The "Ranked actions" sheet lists the courses each existing lane could still recover.
A6: How to read it | B6: "Providers" has one row per university (counts are formulas over the detail sheets, so they update if you filter or correct a row). Each university has a detail sheet with one row per course. "Ranked actions" ranks provider-level actions by courses recoverable, then by evidence quality. "Sources" lists every fee, calendar and English source page and every approval or rejection record.
A7: Advertised status | B7: "Advertised: official page in place" = the course has an active official course page. Other values say why not: a page was found but needs a rendered read; a page was read but not yet admitted; the page address no longer works (HTTP 404/403); the page found is for another course (held); a no-page record (conjoint or no page) is waiting for review; or no page was found at all. "Re-link lane result" shows whether the existing re-link lane has already finished without finding a page.
A8: Register-only courses | B8: Courses on the CRICOS register with no official page. Whether a course appears on the university's own course list cannot be told per course: the course-list reader stores only page counts (for example Melbourne handbook 210 addresses, Macquarie handbook 177, UNSW postgraduate sitemap 289, Sydney 371), not which course each address belongs to.
A9: Recoverable share | B9: Absolute "most missing" counts are not failure rates. Each action shows courses recoverable over that university's active courses.
A10: Evidence quality | B10: 1 = own-domain source with a dated quote; 2 = own-domain quote that is not dated, or months set by hand from an own-domain page; 3 = satellite page (college, campus or partner site); 4 = no quote stored. Lower is better.
A11: Gates | B11: Automatic = the existing lane admits on its own. Layer 4 review = a person decides in Layer 4. Platform Admin decision = a rule or spending decision only the Platform Admin can make. This report proposes no new readers, no PDF work, no widening of providers and no application-deadline or description builds.
A12: Rules referred to | B12: 19 Oct 2026 Platform Admin "Undergraduate only": universities get calendar default months only at bachelor, bachelor honours, associate degree, diploma and advanced diploma. 22 Oct 2026 Platform Admin "Page-only months, no API change": intakes must match the official university website; 2,166 calendar intake rows were withdrawn platform-wide. 23 Oct 2026: delivery values read from another course's page or an earlier page were taken back.
A14: What could not be determined
A15: Intake dates | B15: catalogue.course_intakes has no timestamps, so when an intake row was written or withdrawn cannot be shown. "Intake rows withdrawn earlier" counts non-active rows only.
A16: Fee schedule matching | B16: Sydney and UNSW fee pages show no course codes, so how many courses their rows would match (by title) cannot be counted until rows are kept. The stored page text was not read for this report (stored files are not reachable by read-only SQL).
A17: Melbourne English | B17: Melbourne's approved English rule is a level map applied by a separate step; it was not re-planned per course here. Its last apply: 124 courses unchanged, 0 written, 441 held in the plan summary.
A18: Why some values wait | B18: For "Value found, being checked" (candidate) the exact admission step is not recorded per course; they are listed under Layer 4 review.
A19: Melbourne fee table skips | B19: Why the apply step skipped the 3 Melbourne courses that are in the 2027 fee table but have no fee is not recorded per course (the apply summary shows 584 rows with several amounts, 243 annual amounts used, 9 with no course).
A20: Entry requirements | B20: No entry-requirements source is registered for any of the five (0 sources, 0 rows, 0 runs), so there is no HTML/PDF split to report beyond the related central pages listed on "Providers". Stored files are converted to text, so the original file type is taken from the address (".pdf").
A22: Field states (legend)
A23: State | B23: Meaning
A24: Filled | B24: The field has a value.
A25: Searching for course page | B25: The university website is known; the course page is not found yet.
A26: Page found, being read | B26: A course page is bound; its value is not read or admitted yet (includes pages that need a rendered read or whose address no longer works).
A27: Value found, being checked | B27: A value was read from a CRICOS-proved course page and is not admitted yet.
A28: Waiting for AI reading (Layer 3, now retired) | B28: Queued for Layer 3, which was retired on 15 Oct; these items do not move on their own.
A29: Waiting for Layer 4 review | B29: A person decides in Layer 4.
A30: Not stated on course page | B30: The page was read and does not state it, or no allowed source had a value.
A31: Blocked: needs a person | B31: Held by a rule (for example the site blocks reading).
A32: Not in the CRICOS register | B32: The register gives no value.
A33: Reader not built yet | B33: No reader exists for this field yet.

Sheet Providers
A1: Provider | B1: Active courses | C1: Advertised: official page in place | D1: Page found, needs a rendered read | E1: Page read, not yet admitted | F1: Page address no longer works | G1: Held: page found is for another course | H1: No-page record (conjoint or no page) | I1: No page found | J1: Not advertised or no usable page (total) | K1: % advertised | L1: Re-link lane finished with no page | M1: International fee admitted | N1: In approved fee schedule (CRICOS match) | O1: In schedule but no fee yet | P1: English filled | Q1: English from central policy | R1: English from course page or adapter | S1: Course page disagrees with central English | T1: Intakes filled | U1: Intakes from course page or adapter | V1: No intakes | W1: No intakes, calendar level (undergraduate/diploma) | X1: No intakes, other levels | Y1: Undergraduate with page, calendar intakes withdrawn (22 Oct) | Z1: Delivery mode filled | AA1: Delivery not stated on page | AB1: Delivery taken back 23 Oct (courses) | AC1: Fee schedule source(s) | AD1: Fee schedule matching key vs course keys | AE1: Approved calendar(s) | AF1: Default start months | AG1: Calendar study-level rule | AH1: Approved English policy | AI1: English levels covered | AJ1: Entry-requirements sources (HTML / PDF)
A2: The University of Sydney | B2: =COUNTA('Sydney'!$A$2:$A$656) | C2: =COUNTIF('Sydney'!$E$2:$E$656,"Advertised: official page in place") | D2: =COUNTIF('Sydney'!$E$2:$E$656,"Page found, needs a rendered read") | E2: =COUNTIF('Sydney'!$E$2:$E$656,"Page read, not yet admitted") | F2: =COUNTIF('Sydney'!$E$2:$E$656,"Page address no longer works") | G2: =COUNTIF('Sydney'!$E$2:$E$656,"Held: page found is for another course") | H2: =COUNTIF('Sydney'!$E$2:$E$656,"No-page record*") | I2: =COUNTIF('Sydney'!$E$2:$E$656,"No page found") | J2: =B2-C2 | K2: =IF(B2=0,0,C2/B2) | L2: =COUNTIFS('Sydney'!$K$2:$K$656,"Finished, no page*",'Sydney'!$E$2:$E$656,"<>Advertised: official page in place") | M2: =COUNTIF('Sydney'!$M$2:$M$656,"Filled") | N2: =COUNTIF('Sydney'!$O$2:$O$656,">0") | O2: =COUNTIFS('Sydney'!$O$2:$O$656,">0",'Sydney'!$M$2:$M$656,"<>Filled") | P2: =COUNTIF('Sydney'!$Q$2:$Q$656,"Filled") | Q2: =COUNTIF('Sydney'!$S$2:$S$656,"Central English policy") | R2: =COUNTIF('Sydney'!$S$2:$S$656,"Page reader")+COUNTIF('Sydney'!$S$2:$S$656,"University adapter") | S2: =COUNTIF('Sydney'!$U$2:$U$656,"Yes*") | T2: =COUNTIF('Sydney'!$V$2:$V$656,"Filled") | U2: =COUNTIF('Sydney'!$X$2:$X$656,"Page reader")+COUNTIF('Sydney'!$X$2:$X$656,"University adapter") | V2: =B2-T2 | W2: =COUNTIFS('Sydney'!$V$2:$V$656,"<>Filled",'Sydney'!$Z$2:$Z$656,"Yes") | X2: =COUNTIFS('Sydney'!$V$2:$V$656,"<>Filled",'Sydney'!$Z$2:$Z$656,"No") | Y2: =COUNTIF('Sydney'!$AH$2:$AH$656,"Yes") | Z2: =COUNTIF('Sydney'!$AA$2:$AA$656,"Filled") | AA2: =COUNTIF('Sydney'!$AA$2:$AA$656,"Not stated on course page") | AB2: =COUNTIF('Sydney'!$AD$2:$AD$656,">0") | AC2: sydney.edu.au/study/fees-and-loans/international-student-tuition-fees.html (HTML, own domain). Status: no values; 1 read attempt, read 1 Oct 2026; 41 table rows, 0 course codes seen, fee year 2026. Fee reader (26 Oct) read 41 rows but their quotes were not found on the page; 0 fee rows kept. 3 other fee pages: no values (one is a test page). | AD2: Schedule shows no course codes (0 seen), so it could only match by title or faculty. Courses carry CRICOS code, title and study level; no faculty field is held. Match count cannot be determined until the rows are kept. | AE2: (1) Set by hand 7 Oct, Platform Admin approved: Semester 1 Feb, Semester 2 Aug (source address: student wall calendar PDF). (2) Auto-approved 23 Oct: sydney.edu.au/study/applying/application-dates.html, dated quotes "Semester 1 | 23 February 2026", "Semester 2 | 3 August 2026". Own domain. | AF2: Feb, Aug | AG2: Universities get default months only at bachelor, bachelor honours, associate degree, diploma, advanced diploma (Platform Admin 19 Oct "Undergraduate only"). Since 22 Oct "Page-only months" calendar months were withdrawn (2,166 rows platform-wide): intakes must come from the course page. | AH2: sydney.edu.au English language requirements page (HTML, own domain). Two approvals: 2 Oct (rule-based parser, no decision note) undergraduate + postgraduate IELTS 6.5 (no band below 6.0); 15 Oct (automatic AI reading) research 6.5. Caveats: "some faculties and courses have different requirements". | AI2: Undergraduate, postgraduate, research. Not covered: diploma, non-award; double degrees across levels are held. | AJ2: None registered: 0 entry-requirements (entry matrix) sources, 0 entry matrix rows, 0 runs. Academic entry is "Reader not built yet" for every course. Related central pages held under other kinds: English proficiency tables (PDF); English requirements pages (HTML).
A3: UNSW Sydney | B3: =COUNTA('UNSW'!$A$2:$A$668) | C3: =COUNTIF('UNSW'!$E$2:$E$668,"Advertised: official page in place") | D3: =COUNTIF('UNSW'!$E$2:$E$668,"Page found, needs a rendered read") | E3: =COUNTIF('UNSW'!$E$2:$E$668,"Page read, not yet admitted") | F3: =COUNTIF('UNSW'!$E$2:$E$668,"Page address no longer works") | G3: =COUNTIF('UNSW'!$E$2:$E$668,"Held: page found is for another course") | H3: =COUNTIF('UNSW'!$E$2:$E$668,"No-page record*") | I3: =COUNTIF('UNSW'!$E$2:$E$668,"No page found") | J3: =B3-C3 | K3: =IF(B3=0,0,C3/B3) | L3: =COUNTIFS('UNSW'!$K$2:$K$668,"Finished, no page*",'UNSW'!$E$2:$E$668,"<>Advertised: official page in place") | M3: =COUNTIF('UNSW'!$M$2:$M$668,"Filled") | N3: =COUNTIF('UNSW'!$O$2:$O$668,">0") | O3: =COUNTIFS('UNSW'!$O$2:$O$668,">0",'UNSW'!$M$2:$M$668,"<>Filled") | P3: =COUNTIF('UNSW'!$Q$2:$Q$668,"Filled") | Q3: =COUNTIF('UNSW'!$S$2:$S$668,"Central English policy") | R3: =COUNTIF('UNSW'!$S$2:$S$668,"Page reader")+COUNTIF('UNSW'!$S$2:$S$668,"University adapter") | S3: =COUNTIF('UNSW'!$U$2:$U$668,"Yes*") | T3: =COUNTIF('UNSW'!$V$2:$V$668,"Filled") | U3: =COUNTIF('UNSW'!$X$2:$X$668,"Page reader")+COUNTIF('UNSW'!$X$2:$X$668,"University adapter") | V3: =B3-T3 | W3: =COUNTIFS('UNSW'!$V$2:$V$668,"<>Filled",'UNSW'!$Z$2:$Z$668,"Yes") | X3: =COUNTIFS('UNSW'!$V$2:$V$668,"<>Filled",'UNSW'!$Z$2:$Z$668,"No") | Y3: =COUNTIF('UNSW'!$AH$2:$AH$668,"Yes") | Z3: =COUNTIF('UNSW'!$AA$2:$AA$668,"Filled") | AA3: =COUNTIF('UNSW'!$AA$2:$AA$668,"Not stated on course page") | AB3: =COUNTIF('UNSW'!$AD$2:$AD$668,">0") | AC3: unsw.edu.au/student/managing-your-studies/fees/international (HTML, own domain). Status: no values; 1 attempt, read 1 Oct 2026; 327 table rows, 0 course codes seen, fee year 2026. Fee reader (26 Oct): no rows. 4 other fee pages (incl. 2 archives): no values. Admitted fees come from course pages (adapter 279, page reader 19). | AD3: Schedule shows no CRICOS codes (0 seen). Courses carry CRICOS code, title, study level; UNSW programme codes appear only inside some page addresses. Match count not determinable. | AE3: (1) Set by hand 7 Oct, Platform Admin approved: UNSW academic calendar Term 1 Feb, Term 2 Jun, Term 3 Sep (own domain, no stored quote). (2) Auto-approved 14 Oct: key-dates page, quote "Term 1 March 2023" (out of date). (3) Auto-approved 23 Oct: unswglobal.unsw.edu.au key dates (UNSW College, a satellite page): Term 1-3 2027, Semester 1-2 2028. | AF3: Feb, Jun | AG3: Universities get default months only at bachelor, bachelor honours, associate degree, diploma, advanced diploma (Platform Admin 19 Oct "Undergraduate only"). Since 22 Oct "Page-only months" calendar months were withdrawn (2,166 rows platform-wide): intakes must come from the course page. | AH3: APPROVED source is unsw.edu.au/bengaluru English requirements (UNSW India campus page, satellite), approved 2 Oct by the rule-based parser (no decision note): undergraduate + postgraduate IELTS 6.0 (5.5 each). On 17 Oct the Platform Admin REJECTED a later reading of the same Bengaluru page ("India campus page, not the Sydney policy") and the Sydney page reading ("one faculty row ... 429 course pages differ"). The 2 Oct approval is still in force. | AI3: Undergraduate, postgraduate only (no research default). Diploma, non-award held. | AJ3: None registered: 0 entry-requirements (entry matrix) sources, 0 entry matrix rows, 0 runs. Academic entry is "Reader not built yet" for every course. Related central pages held under other kinds: International entry requirements page (HTML, held as an English source).
A4: Macquarie University | B4: =COUNTA('Macquarie'!$A$2:$A$462) | C4: =COUNTIF('Macquarie'!$E$2:$E$462,"Advertised: official page in place") | D4: =COUNTIF('Macquarie'!$E$2:$E$462,"Page found, needs a rendered read") | E4: =COUNTIF('Macquarie'!$E$2:$E$462,"Page read, not yet admitted") | F4: =COUNTIF('Macquarie'!$E$2:$E$462,"Page address no longer works") | G4: =COUNTIF('Macquarie'!$E$2:$E$462,"Held: page found is for another course") | H4: =COUNTIF('Macquarie'!$E$2:$E$462,"No-page record*") | I4: =COUNTIF('Macquarie'!$E$2:$E$462,"No page found") | J4: =B4-C4 | K4: =IF(B4=0,0,C4/B4) | L4: =COUNTIFS('Macquarie'!$K$2:$K$462,"Finished, no page*",'Macquarie'!$E$2:$E$462,"<>Advertised: official page in place") | M4: =COUNTIF('Macquarie'!$M$2:$M$462,"Filled") | N4: =COUNTIF('Macquarie'!$O$2:$O$462,">0") | O4: =COUNTIFS('Macquarie'!$O$2:$O$462,">0",'Macquarie'!$M$2:$M$462,"<>Filled") | P4: =COUNTIF('Macquarie'!$Q$2:$Q$462,"Filled") | Q4: =COUNTIF('Macquarie'!$S$2:$S$462,"Central English policy") | R4: =COUNTIF('Macquarie'!$S$2:$S$462,"Page reader")+COUNTIF('Macquarie'!$S$2:$S$462,"University adapter") | S4: =COUNTIF('Macquarie'!$U$2:$U$462,"Yes*") | T4: =COUNTIF('Macquarie'!$V$2:$V$462,"Filled") | U4: =COUNTIF('Macquarie'!$X$2:$X$462,"Page reader")+COUNTIF('Macquarie'!$X$2:$X$462,"University adapter") | V4: =B4-T4 | W4: =COUNTIFS('Macquarie'!$V$2:$V$462,"<>Filled",'Macquarie'!$Z$2:$Z$462,"Yes") | X4: =COUNTIFS('Macquarie'!$V$2:$V$462,"<>Filled",'Macquarie'!$Z$2:$Z$462,"No") | Y4: =COUNTIFS('Macquarie'!$V$2:$V$462,"<>Filled",'Macquarie'!$Z$2:$Z$462,"Yes",'Macquarie'!$Y$2:$Y$462,">0",'Macquarie'!$E$2:$E$462,"Advertised: official page in place") | Z4: =COUNTIF('Macquarie'!$AA$2:$AA$462,"Filled") | AA4: =COUNTIF('Macquarie'!$AA$2:$AA$462,"Not stated on course page") | AB4: =COUNTIF('Macquarie'!$AD$2:$AD$462,">0") | AC4: mq.edu.au/study/admissions-and-entry/fees-and-costs/international (HTML, own domain). Status: no values; 1 attempt, read 1 Oct 2026; 0 table rows. 2 other pages (incl. refund policy): no values. Fee reader (26 Oct): no rows. No admitted fees. | AD4: No fee table on the central pages, so no matching key. Courses carry CRICOS code, title, study level. | AE4: Only approved calendar (auto, 14 Oct) is the English language programs dates page (9 "English Block" start dates, 2026). It is not a degree calendar. The two degree date pages (students.mq.edu.au) gave no values. | AF4: None (no semester/term 1 period in the approved calendar) | AG4: Universities get default months only at bachelor, bachelor honours, associate degree, diploma, advanced diploma (Platform Admin 19 Oct "Undergraduate only"). Since 22 Oct "Page-only months" calendar months were withdrawn (2,166 rows platform-wide): intakes must come from the course page. | AH4: Two automatic AI approvals (14 Oct): mq.edu.au English language requirements (HTML) undergraduate + postgraduate IELTS 6.5; graduate research Schedule 1 (PDF, own domain) research 6.5. | AI4: Undergraduate, postgraduate, research. Diploma, non-award held; 213 double degrees held. | AJ4: None registered: 0 entry-requirements (entry matrix) sources, 0 entry matrix rows, 0 runs. Academic entry is "Reader not built yet" for every course. Related central pages held under other kinds: International academic requirements page (HTML, held as an English source); graduate research English schedule (PDF).
A5: Australian National University | B5: =COUNTA('ANU'!$A$2:$A$424) | C5: =COUNTIF('ANU'!$E$2:$E$424,"Advertised: official page in place") | D5: =COUNTIF('ANU'!$E$2:$E$424,"Page found, needs a rendered read") | E5: =COUNTIF('ANU'!$E$2:$E$424,"Page read, not yet admitted") | F5: =COUNTIF('ANU'!$E$2:$E$424,"Page address no longer works") | G5: =COUNTIF('ANU'!$E$2:$E$424,"Held: page found is for another course") | H5: =COUNTIF('ANU'!$E$2:$E$424,"No-page record*") | I5: =COUNTIF('ANU'!$E$2:$E$424,"No page found") | J5: =B5-C5 | K5: =IF(B5=0,0,C5/B5) | L5: =COUNTIFS('ANU'!$K$2:$K$424,"Finished, no page*",'ANU'!$E$2:$E$424,"<>Advertised: official page in place") | M5: =COUNTIF('ANU'!$M$2:$M$424,"Filled") | N5: =COUNTIF('ANU'!$O$2:$O$424,">0") | O5: =COUNTIFS('ANU'!$O$2:$O$424,">0",'ANU'!$M$2:$M$424,"<>Filled") | P5: =COUNTIF('ANU'!$Q$2:$Q$424,"Filled") | Q5: =COUNTIF('ANU'!$S$2:$S$424,"Central English policy") | R5: =COUNTIF('ANU'!$S$2:$S$424,"Page reader")+COUNTIF('ANU'!$S$2:$S$424,"University adapter") | S5: =COUNTIF('ANU'!$U$2:$U$424,"Yes*") | T5: =COUNTIF('ANU'!$V$2:$V$424,"Filled") | U5: =COUNTIF('ANU'!$X$2:$X$424,"Page reader")+COUNTIF('ANU'!$X$2:$X$424,"University adapter") | V5: =B5-T5 | W5: =COUNTIFS('ANU'!$V$2:$V$424,"<>Filled",'ANU'!$Z$2:$Z$424,"Yes") | X5: =COUNTIFS('ANU'!$V$2:$V$424,"<>Filled",'ANU'!$Z$2:$Z$424,"No") | Y5: =COUNTIFS('ANU'!$V$2:$V$424,"<>Filled",'ANU'!$Z$2:$Z$424,"Yes",'ANU'!$Y$2:$Y$424,">0",'ANU'!$E$2:$E$424,"Advertised: official page in place") | Z5: =COUNTIF('ANU'!$AA$2:$AA$424,"Filled") | AA5: =COUNTIF('ANU'!$AA$2:$AA$424,"Not stated on course page") | AB5: =COUNTIF('ANU'!$AD$2:$AD$424,">0") | AC5: anu.edu.au/students/program-administration/fees-payments/international-tuition-fees (HTML, own domain). Status: no values; 1 attempt, read 1 Oct 2026; 0 table rows, fee year 2026. 3 other pages: no values. Admitted fees come from course pages (adapter 351, other 14). | AD5: No fee table on the central pages, so no matching key. Courses carry CRICOS code, title, study level. | AE5: None approved. All three pages (CBE key dates, university calendar 2026 and 2027) gave no values. | AF5: None (no semester/term 1 period in the approved calendar) | AG5: Universities get default months only at bachelor, bachelor honours, associate degree, diploma, advanced diploma (Platform Admin 19 Oct "Undergraduate only"). Since 22 Oct "Page-only months" calendar months were withdrawn (2,166 rows platform-wide): intakes must come from the course page. | AH5: policies.anu.edu.au English language admission requirements policy (HTML, own domain), written out by hand from the stored page; Platform Admin approved 17 Oct (Decision 264): undergraduate, postgraduate, research IELTS 6.5 (6.0 each) + 4 named exceptions. | AI5: Undergraduate, postgraduate, research (+4 named courses). Diploma, non-award held. | AJ5: None registered: 0 entry-requirements (entry matrix) sources, 0 entry matrix rows, 0 runs. Academic entry is "Reader not built yet" for every course. Related central pages held under other kinds: English requirements, ANU policy library and English language program pages (all HTML).
A6: The University of Melbourne | B6: =COUNTA('Melbourne'!$A$2:$A$442) | C6: =COUNTIF('Melbourne'!$E$2:$E$442,"Advertised: official page in place") | D6: =COUNTIF('Melbourne'!$E$2:$E$442,"Page found, needs a rendered read") | E6: =COUNTIF('Melbourne'!$E$2:$E$442,"Page read, not yet admitted") | F6: =COUNTIF('Melbourne'!$E$2:$E$442,"Page address no longer works") | G6: =COUNTIF('Melbourne'!$E$2:$E$442,"Held: page found is for another course") | H6: =COUNTIF('Melbourne'!$E$2:$E$442,"No-page record*") | I6: =COUNTIF('Melbourne'!$E$2:$E$442,"No page found") | J6: =B6-C6 | K6: =IF(B6=0,0,C6/B6) | L6: =COUNTIFS('Melbourne'!$K$2:$K$442,"Finished, no page*",'Melbourne'!$E$2:$E$442,"<>Advertised: official page in place") | M6: =COUNTIF('Melbourne'!$M$2:$M$442,"Filled") | N6: =COUNTIF('Melbourne'!$O$2:$O$442,">0") | O6: =COUNTIFS('Melbourne'!$O$2:$O$442,">0",'Melbourne'!$M$2:$M$442,"<>Filled") | P6: =COUNTIF('Melbourne'!$Q$2:$Q$442,"Filled") | Q6: =COUNTIF('Melbourne'!$S$2:$S$442,"Central English policy") | R6: =COUNTIF('Melbourne'!$S$2:$S$442,"Page reader")+COUNTIF('Melbourne'!$S$2:$S$442,"University adapter") | S6: =COUNTIF('Melbourne'!$U$2:$U$442,"Yes*") | T6: =COUNTIF('Melbourne'!$V$2:$V$442,"Filled") | U6: =COUNTIF('Melbourne'!$X$2:$X$442,"Page reader")+COUNTIF('Melbourne'!$X$2:$X$442,"University adapter") | V6: =B6-T6 | W6: =COUNTIFS('Melbourne'!$V$2:$V$442,"<>Filled",'Melbourne'!$Z$2:$Z$442,"Yes") | X6: =COUNTIFS('Melbourne'!$V$2:$V$442,"<>Filled",'Melbourne'!$Z$2:$Z$442,"No") | Y6: =COUNTIF('Melbourne'!$AH$2:$AH$442,"Yes") | Z6: =COUNTIF('Melbourne'!$AA$2:$AA$442,"Filled") | AA6: =COUNTIF('Melbourne'!$AA$2:$AA$442,"Not stated on course page") | AB6: =COUNTIF('Melbourne'!$AD$2:$AD$442,">0") | AC6: study.unimelb.edu.au/.../2027InternationalFeeTables.pdf (PDF, own domain). Status: parsed and APPROVED 1 Oct 2026; 1 attempt, read 1 Oct 2026; 838 fee rows, 296 codes seen, fee year 2027. Graduate 2027 table and 2026 graduate coursework PDF links return 404 (26 Oct). 9 other fee pages: no values. | AD6: Schedule is keyed by CRICOS code (294 distinct codes in 838 current rows); every course carries its CRICOS code. 291 courses match; 288 of them already have a fee. | AE6: (1) Set by hand 7 Oct, Platform Admin approved: unimelb.edu.au/dates/semester-dates, Semester 1 Mar (2 Mar 2026), Semester 2 Jul (27 Jul 2026); no stored quote. (2) Auto-approved 14 Oct: Ormond College key dates (satellite). (3) Auto-approved 23 Oct: Trinity College key dates (satellite). | AF6: Mar, Jul | AG6: Universities get default months only at bachelor, bachelor honours, associate degree, diploma, advanced diploma (Platform Admin 19 Oct "Undergraduate only"). Since 22 Oct "Page-only months" calendar months were withdrawn (2,166 rows platform-wide): intakes must come from the course page. | AH6: study.unimelb.edu.au English language requirements (HTML, own domain), level map written out by hand; Platform Admin approved 18 Oct (Decision 265). Caveats: bands give an overall score only; research degrees state no level. Last apply: 124 courses unchanged, 0 written. | AI6: By the university's own English level per course (level map), not by study level. Research degrees state no level. | AJ6: None registered: 0 entry-requirements (entry matrix) sources, 0 entry matrix rows, 0 runs. Academic entry is "Reader not built yet" for every course. Related central pages held under other kinds: English requirements pages (HTML, 3).
A7: All five | B7: =SUM(B2:B6) | C7: =SUM(C2:C6) | D7: =SUM(D2:D6) | E7: =SUM(E2:E6) | F7: =SUM(F2:F6) | G7: =SUM(G2:G6) | H7: =SUM(H2:H6) | I7: =SUM(I2:I6) | J7: =SUM(J2:J6) | K7: =IF(B7=0,0,C7/B7) | L7: =SUM(L2:L6) | M7: =SUM(M2:M6) | N7: =SUM(N2:N6) | O7: =SUM(O2:O6) | P7: =SUM(P2:P6) | Q7: =SUM(Q2:Q6) | R7: =SUM(R2:R6) | S7: =SUM(S2:S6) | ... AB7: =SUM(AB2:AB6)

Sheet Ranked actions
A1: Rank | B1: Provider | C1: Action | D1: Lane (existing) | E1: Gate | F1: Evidence | G1: Evidence quality | H1: Courses recoverable | I1: Active courses (denominator) | J1: Recoverable share | K1: Note
A2: 1 | B2: The University of Sydney | C2: Give postgraduate and research courses (with an official page, no intakes) the approved calendar start months | D2: Calendar default intakes (existing apply step) | E2: Platform Admin decision: reverse 19 Oct "Undergraduate only" AND make an exception to 22 Oct "Page-only months" | F2: sydney.edu.au application-dates: "Semester 1 | 23 February 2026", "Semester 2 | 3 August 2026" (auto-approved 23 Oct) + set by hand 7 Oct. | G2: 1 Own-domain dated source | H2: =COUNTIF('Sydney'!$AI$2:$AI$656,"Yes") | I2: =Providers!B2 | J2: =IF(I2=0,0,H2/I2) | K2: The calendars quote semester/term starts, not level-specific starts; whether they hold for postgraduate and research entry is not proven.
A3: 2 | B3: The University of Melbourne | C3: Give postgraduate and research courses (with an official page, no intakes) the approved calendar start months | D3: Calendar default intakes (existing apply step) | E3: Platform Admin decision: reverse 19 Oct "Undergraduate only" AND make an exception to 22 Oct "Page-only months" | F3: unimelb.edu.au semester dates set by hand 7 Oct (2 Mar / 27 Jul 2026); dated quotes only on Ormond and Trinity college pages (satellite). | G3: 2 Own-domain quote, not dated (or set by hand) | H3: =COUNTIF('Melbourne'!$AI$2:$AI$442,"Yes") | I3: =Providers!B6 | J3: =IF(I3=0,0,H3/I3) | K3: The calendars quote semester/term starts, not level-specific starts; whether they hold for postgraduate and research entry is not proven.
A4: 3 | B4: The University of Sydney | C4: Give undergraduate courses (with an official page) the approved calendar start months that were withdrawn on 22 Oct | D4: Calendar default intakes (existing apply step) | E4: Platform Admin decision: exception to 22 Oct "Page-only months" | F4: sydney.edu.au application-dates: "Semester 1 | 23 February 2026", "Semester 2 | 3 August 2026" (auto-approved 23 Oct) + set by hand 7 Oct. | G4: 1 Own-domain dated source | H4: =COUNTIF('Sydney'!$AH$2:$AH$656,"Yes") | I4: =Providers!B2 | J4: =IF(I4=0,0,H4/I4) | K4: Courses had calendar intakes before 22 Oct; withdrawn under the page-only rule.
A5: 4 | B5: Macquarie University | C5: Apply the approved central English default to course types the plan holds (diploma, non-award, double degrees across levels, research where no default) | D5: Central English policy apply (existing) | E5: Platform Admin decision (rule for held course types) | F5: Own-domain central page quote: "Competent | 6.5 | 6.0 ... | Most undergraduate or postgraduate courses". | G5: 2 Own-domain quote, not dated (or set by hand) | H5: =COUNTIF('Macquarie'!$AJ$2:$AJ$462,"Yes") | I5: =Providers!B4 | J5: =IF(I5=0,0,H5/I5) | K5: Uses the already-approved central English source.
A6: 5 | B6: The University of Sydney | C6: Read the bound course page again with a rendered (scraper) read, then let the identity check and Enrich fields run on it | D6: Read pages again (existing admin job) -> course-page identity check -> Enrich fields | E6: Platform Admin starts the job (uses scraper credit); identity check and field reads are automatic | F6: Own-domain course page address returns HTTP 200 but the direct read needs rendering; no quote stored yet; identity not yet proved. | G6: 4 No quote stored | H6: =COUNTIF('Sydney'!$AE$2:$AE$656,"Yes") | I6: =Providers!B2 | J6: =IF(I6=0,0,H6/I6) | K6: Recovers the official page where none is in place, then page-read fields (delivery, intakes, English, fee).
A7: 6 | B7: Australian National University | C7: Review values already read from the course's own page (tuition, intakes or English) that are waiting to be checked | D7: Coverage pipeline: page value -> Layer 4 | E7: Layer 4 review | F7: Quote on the bound course page (own domain), not dated. | G7: 2 Own-domain quote, not dated (or set by hand) | H7: =COUNTIF('ANU'!$AF$2:$AF$424,"Yes") | I7: =Providers!B5 | J7: =IF(I7=0,0,H7/I7) | K7: Values are already quoted from the bound course page.
A8: 7 | B8: The University of Sydney | C8: Apply the approved central English default to course types the plan holds (diploma, non-award, double degrees across levels, research where no default) | D8: Central English policy apply (existing) | E8: Platform Admin decision (rule for held course types) | F8: Own-domain central page quote: "standard ... IELTS overall score of 6.5 with no band below 6.0; however, some faculties and courses have different requirements". | G8: 2 Own-domain quote, not dated (or set by hand) | H8: =COUNTIF('Sydney'!$AJ$2:$AJ$656,"Yes") | I8: =Providers!B2 | J8: =IF(I8=0,0,H8/I8) | K8: Uses the already-approved central English source.
A9: 8 | B9: The University of Melbourne | C9: Read the bound course page again with a rendered (scraper) read, then let the identity check and Enrich fields run on it | D9: Read pages again (existing admin job) -> course-page identity check -> Enrich fields | E9: Platform Admin starts the job (uses scraper credit); identity check and field reads are automatic | F9: Own-domain course page address returns HTTP 200 but the direct read needs rendering; no quote stored yet; identity not yet proved. | G9: 4 No quote stored | H9: =COUNTIF('Melbourne'!$AE$2:$AE$442,"Yes") | I9: =Providers!B6 | J9: =IF(I9=0,0,H9/I9) | K9: Recovers the official page where none is in place, then page-read fields (delivery, intakes, English, fee).
A10: 9 | B10: The University of Melbourne | C10: Review values already read from the course's own page (tuition, intakes or English) that are waiting to be checked | D10: Coverage pipeline: page value -> Layer 4 | E10: Layer 4 review | F10: Quote on the bound course page (own domain), not dated. | G10: 2 Own-domain quote, not dated (or set by hand) | H10: =COUNTIF('Melbourne'!$AF$2:$AF$442,"Yes") | I10: =Providers!B6 | J10: =IF(I10=0,0,H10/I10) | K10: Values are already quoted from the bound course page.
A11: 10 | B11: Australian National University | C11: Apply the approved central English default to course types the plan holds (diploma, non-award, double degrees across levels, research where no default) | D11: Central English policy apply (existing) | E11: Platform Admin decision (rule for held course types) | F11: ANU policy library, written out from the stored page (Decision 264). | G11: 2 Own-domain quote, not dated (or set by hand) | H11: =COUNTIF('ANU'!$AJ$2:$AJ$424,"Yes") | I11: =Providers!B5 | J11: =IF(I11=0,0,H11/I11) | K11: Uses the already-approved central English source.
A12: 11 | B12: The University of Melbourne | C12: Give undergraduate courses (with an official page) the approved calendar start months that were withdrawn on 22 Oct | D12: Calendar default intakes (existing apply step) | E12: Platform Admin decision: exception to 22 Oct "Page-only months" | F12: unimelb.edu.au semester dates set by hand 7 Oct (2 Mar / 27 Jul 2026); dated quotes only on Ormond and Trinity college pages (satellite). | G12: 2 Own-domain quote, not dated (or set by hand) | H12: =COUNTIF('Melbourne'!$AH$2:$AH$442,"Yes") | I12: =Providers!B6 | J12: =IF(I12=0,0,H12/I12) | K12: Courses had calendar intakes before 22 Oct; withdrawn under the page-only rule.
A13: 12 | B13: Australian National University | C13: Re-route items still waiting for Layer 3 (retired 15 Oct) so they reach Layer 4 | D13: Coverage pipeline (Layer 3 items in pending/failed) | E13: Layer 4 review (after re-routing) | F13: Quote on the bound course page (own domain), not dated. | G13: 2 Own-domain quote, not dated (or set by hand) | H13: =COUNTIF('ANU'!$AG$2:$AG$424,"Yes") | I13: =Providers!B5 | J13: =IF(I13=0,0,H13/I13) | K13: Layer 3 is retired (CF-247 15 Oct, usage audit D6); these items will not move on their own.
A14: 13 | B14: The University of Sydney | C14: Re-run Enrich fields for delivery where the AI gave a value but its quote was not found on the page | D14: Enrich fields (existing) | E14: Automatic (after the quote-matching tuning already identified on 26 Oct, class B) | F14: AI value whose quote was not found on the stored page. | G14: 4 No quote stored | H14: =COUNTIF('Sydney'!$AK$2:$AK$656,"Yes") | I14: =Providers!B2 | J14: =IF(I14=0,0,H14/I14) | K14: Value proposed but quote not matched on the page.
A15: 14 | B15: The University of Sydney | C15: Review values already read from the course's own page (tuition, intakes or English) that are waiting to be checked | D15: Coverage pipeline: page value -> Layer 4 | E15: Layer 4 review | F15: Quote on the bound course page (own domain), not dated. | G15: 2 Own-domain quote, not dated (or set by hand) | H15: =COUNTIF('Sydney'!$AF$2:$AF$656,"Yes") | I15: =Providers!B2 | J15: =IF(I15=0,0,H15/I15) | K15: Values are already quoted from the bound course page.
A16: 15 | B16: UNSW Sydney | C16: Give undergraduate courses (with an official page) the approved calendar start months that were withdrawn on 22 Oct | D16: Calendar default intakes (existing apply step) | E16: Platform Admin decision: exception to 22 Oct "Page-only months" | F16: UNSW academic calendar set by hand 7 Oct (Term 1 Feb, Term 2 Jun); dated quotes only on UNSW College (satellite) and a 2023 key-dates line. Default months skip Term 3 (Sep). | G16: 2 Own-domain quote, not dated (or set by hand) | H16: =COUNTIF('UNSW'!$AH$2:$AH$668,"Yes") | I16: =Providers!B3 | J16: =IF(I16=0,0,H16/I16) | K16: Courses had calendar intakes before 22 Oct; withdrawn under the page-only rule.
A17: 16 | B17: The University of Melbourne | C17: Admit the international fee from the approved 2027 Melbourne fee table for courses in the table that still have no fee | D17: Central fee schedule apply (existing, already parsed) | E17: Layer 4 review (why the apply step skipped them is not recorded per course) | F17: Own-domain 2027 international fee table (approved 1 Oct), CRICOS-keyed row per course. | G17: 1 Own-domain dated source | H17: =COUNTIF('Melbourne'!$AL$2:$AL$442,"Yes") | I17: =Providers!B6 | J17: =IF(I17=0,0,H17/I17) | K17: Approved 2027 international fee table keyed by CRICOS code.
A18: 17 | B18: UNSW Sydney | C18: Re-route items still waiting for Layer 3 (retired 15 Oct) so they reach Layer 4 | D18: Coverage pipeline (Layer 3 items in pending/failed) | E18: Layer 4 review (after re-routing) | F18: Quote on the bound course page (own domain), not dated. | G18: 2 Own-domain quote, not dated (or set by hand) | H18: =COUNTIF('UNSW'!$AG$2:$AG$668,"Yes") | I18: =Providers!B3 | J18: =IF(I18=0,0,H18/I18) | K18: Layer 3 is retired (CF-247 15 Oct, usage audit D6); these items will not move on their own.
A19: 18 | B19: Macquarie University | C19: Review values already read from the course's own page (tuition, intakes or English) that are waiting to be checked | D19: Coverage pipeline: page value -> Layer 4 | E19: Layer 4 review | F19: Quote on the bound course page (own domain), not dated. | G19: 2 Own-domain quote, not dated (or set by hand) | H19: =COUNTIF('Macquarie'!$AF$2:$AF$462,"Yes") | I19: =Providers!B4 | J19: =IF(I19=0,0,H19/I19) | K19: Values are already quoted from the bound course page.
A20: 19 | B20: The University of Sydney | C20: Re-route items still waiting for Layer 3 (retired 15 Oct) so they reach Layer 4 | D20: Coverage pipeline (Layer 3 items in pending/failed) | E20: Layer 4 review (after re-routing) | F20: Quote on the bound course page (own domain), not dated. | G20: 2 Own-domain quote, not dated (or set by hand) | H20: =COUNTIF('Sydney'!$AG$2:$AG$656,"Yes") | I20: =Providers!B2 | J20: =IF(I20=0,0,H20/I20) | K20: Layer 3 is retired (CF-247 15 Oct, usage audit D6); these items will not move on their own.
A21: 20 | B21: UNSW Sydney | C21: Review values already read from the course's own page (tuition, intakes or English) that are waiting to be checked | D21: Coverage pipeline: page value -> Layer 4 | E21: Layer 4 review | F21: Quote on the bound course page (own domain), not dated. | G21: 2 Own-domain quote, not dated (or set by hand) | H21: =COUNTIF('UNSW'!$AF$2:$AF$668,"Yes") | I21: =Providers!B3 | J21: =IF(I21=0,0,H21/I21) | K21: Values are already quoted from the bound course page.
A22: 21 | B22: Macquarie University | C22: Re-run Enrich fields for delivery where the AI gave a value but its quote was not found on the page | D22: Enrich fields (existing) | E22: Automatic (after the quote-matching tuning already identified on 26 Oct, class B) | F22: AI value whose quote was not found on the stored page. | G22: 4 No quote stored | H22: =COUNTIF('Macquarie'!$AK$2:$AK$462,"Yes") | I22: =Providers!B4 | J22: =IF(I22=0,0,H22/I22) | K22: Value proposed but quote not matched on the page.
A24: Not ranked: findings that are not recoveries, or whose course count cannot be determined
B26: Provider | C26: Finding | D26: Lane | E26: Gate | F26: Evidence | G26: Evidence quality | H26: Courses | I26: Denominator | K26: Note
B27: UNSW Sydney | C27: Quality risk: English values from a satellite page | D27: Central English policy (approved 2 Oct) | E27: Platform Admin decision (keep, withdraw or replace the 2 Oct approval) | F27: The approved UNSW English source is the UNSW Bengaluru (India campus) page, IELTS 6.0 (5.5 each). It has written 6.0 to 422 courses. On 17 Oct the Platform Admin rejected a later reading of the same page as "not the Sydney policy". 7 courses whose own page states another score already disagree. Until this is settled, extending the rule to the 236 UNSW courses with no English (173 research degrees, 36 non-award, 21 double degrees, 6 diplomas) is not ranked as a recovery. | G27: 3 Satellite page | H27: =COUNTIF('UNSW'!$S$2:$S$668,"Central English policy") | I27: =Providers!B3 | K27: Courses at risk, not recoverable
B28: The University of Sydney | C28: Fee page: 41 rows read, quotes not found | D28: Fee reader (existing), 26 Oct run | E28: Automatic once quote matching works on this page | F28: sydney.edu.au international tuition fees page (own domain, fee year 2026): reader read 41 rows, finding "quote_missing" for all 41; no course codes on the page, so matching would be by title. | G28: 1 Own-domain dated source | H28: Not determinable | I28: =Providers!B2 | K28: Course count cannot be determined until the rows are kept and matched
B29: Four providers | C29: Confirm no-page records (conjoint or no page) | D29: No-page review (existing; trust state "first run", sample 0) | E29: Layer 4 review | F29: Records proposed by the no-page inventory; confirming them takes the courses out of the "missing official page" count. Fills no field. | G29: 4 No quote stored | H29: =COUNTIF('Sydney'!$AM$2:$AM$656,"Yes")+COUNTIF('UNSW'!$AM$2:$AM$668,"Yes")+COUNTIF('Macquarie'!$AM$2:$AM$462,"Yes")+COUNTIF('ANU'!$AM$2:$AM$424,"Yes")+COUNTIF('Melbourne'!$AM$2:$AM$442,"Yes") | I29: =Providers!B7 | K29: Denominator clean-up only
B30: All five | C30: Pages whose address no longer works or that belong to another course | D30: Re-link and title search (existing) | E30: None open: re-link finished with no page | F30: Most of these courses were sent to re-link and it finished with "no address from the university's address forms" or "every candidate address was refused". No existing lane has more to try. | G30: 4 No quote stored | H30: =SUM(Providers!F2:G6) | I30: =Providers!B7 | K30: Not recoverable through an existing lane

Sheet Sydney
A1: CRICOS code | B1: Course title | C1: Study level | D1: Study level group | E1: Advertised status | F1: Official course page (in place) | G1: Page found (address) | H1: Page read result | I1: Identity proof | J1: No-page record | K1: Re-link lane result | L1: Official course page (state) | M1: International tuition (state) | N1: International fee (amount, year) | O1: Rows in approved fee schedule (by CRICOS code) | P1: Fee source | Q1: English requirement (state) | R1: IELTS overall | S1: English source | T1: Central English rule for this course | U1: Course page disagrees with central English | V1: Intakes (state) | W1: Intake months | X1: Intakes source | Y1: Intake rows withdrawn earlier | Z1: Calendar months allowed at this level (19 Oct rule) | AA1: Delivery mode (state) | AB1: Delivery mode | AC1: Delivery: last reader result | AD1: Delivery values taken back (23 Oct) | AE1: Action: read the bound page again (rendered) | AF1: Action: Layer 4 review of a value read from the course page | AG1: Action: re-route item stuck in retired Layer 3 | AH1: Action: calendar months, undergraduate (22 Oct rule) | AI1: Action: calendar months, postgraduate/research (19 + 22 Oct rules) | AJ1: Action: English rule for held course types | AK1: Action: delivery quote not found, re-run | AL1: Action: fee in approved schedule, not admitted | AM1: Action: confirm no-page record
A2: 086045J | B2: Advanced Skills for Academic Success | C2: Non AQF Award | D2: Non-award | E2: Advertised: official page in place | F2: https://www.sydney.edu.au/cet/programs/succeed/advanced-skills-for-academic-success.html | G2: https://www.sydney.edu.au/cet/programs/succeed/advanced-skills-for-academic-success.html | H2: Read | I2: CRICOS code on page | K2: Not sent to re-link | L2: Filled | M2: Value found, being checked | O2: 0 | Q2: Not stated on course page | T2: Held: level not covered by the policy default | V2: Not stated on course page | Y2: 0 | Z2: No | AA2: Filled | AB2: on campus | AC2: Filled | AD2: 0 | AF2: Yes | AI2: Yes | AJ2: Yes
A3: 093855E | B3: Bachelor of Advanced Computing | C3: Bachelor | D3: Undergraduate | E3: Advertised: official page in place | F3: https://www.sydney.edu.au/courses/courses/uc/bachelor-of-advanced-computing.html | G3: https://www.sydney.edu.au/courses/courses/uc/bachelor-of-advanced-computing.html | H3: Read | I3: Exact title match | K3: Not sent to re-link | L3: Filled | M3: Not stated on course page | O3: 0 | Q3: Filled | R3: 6.5 | S3: Central English policy | T3: Central rule applies (value agrees) | V3: Not stated on course page | Y3: 2 | Z3: Yes | AA3: Filled | AB3: on campus | AD3: 0 | AH3: Yes
A4: 093857C | B4: Bachelor of Advanced Computing/Bachelor of Commerce | C4: Bachelor | D4: Undergraduate | E4: Advertised: official page in place | F4: https://www.sydney.edu.au/handbooks/archive/2025/business-school/advanced-computing-commerce.html | G4: https://www.sydney.edu.au/handbooks/archive/2025/business-school/advanced-computing-commerce.html | H4: Read | I4: CRICOS code on page | K4: Not sent to re-link | L4: Filled | M4: Not stated on course page | O4: 0 | Q4: Filled | R4: 6.5 | S4: Central English policy | T4: Central rule applies (value agrees) | V4: Not stated on course page | Y4: 2 | Z4: Yes | AA4: Not stated on course page | AC4: Skipped: the page does not state it | AD4: 0 | AH4: Yes
A5: 093856D | B5: Bachelor of Advanced Computing/Bachelor of Science | C5: Bachelor | D5: Undergraduate | E5: Page address no longer works | G5: https://www.sydney.edu.au/courses/courses/uc/bachelor-of-advanced-computing-bachelor-of-science.html | H5: Address no longer works | K5: Finished, no page: every candidate address was refused by the reader or did not | L5: Page found, being read | M5: Page found, being read | O5: 0 | Q5: Filled | R5: 6.5 | S5: Central English policy | T5: Central rule applies (value agrees) | V5: Page found, being read | Y5: 0 | Z5: Yes | AA5: Not stated on course page | AC5: Skipped: no allowed source had a value | AD5: 1
A6: 099884G | B6: Bachelor of Advanced Studies | C6: Bachelor | D6: Undergraduate | E6: Advertised: official page in place | F6: https://www.sydney.edu.au/handbooks/interdisciplinary-studies/b-advanced-studies-honours/overview.html | G6: https://www.sydney.edu.au/handbooks/interdisciplinary-studies/b-advanced-studies-honours/overview.html | H6: Read | I6: Exact title match | K6: Not sent to re-link | L6: Filled | M6: Not stated on course page | O6: 0 | Q6: Filled | R6: 6.5 | S6: Central English policy | T6: Central rule applies (value agrees) | V6: Not stated on course page | Y6: 2 | Z6: Yes | AA6: Not stated on course page | AC6: Skipped: the page does not state it | AD6: 0 | AH6: Yes
A7: 0100199 | B7: Bachelor of Advanced Studies (Honours) | C7: Bachelor Honours Degree | D7: Undergraduate | E7: Advertised: official page in place | F7: https://www.sydney.edu.au/handbooks/interdisciplinary-studies/b-advanced-studies-honours/overview.html | G7: https://www.sydney.edu.au/handbooks/interdisciplinary-studies/b-advanced-studies-honours/overview.html | H7: Read | I7: Exact title match | K7: Not sent to re-link | L7: Filled | M7: Not stated on course page | O7: 0 | Q7: Filled | R7: 6.5 | S7: Central English policy | T7: Central rule applies (value agrees) | V7: Not stated on course page | Y7: 2 | Z7: Yes | AA7: Not stated on course page | AC7: Skipped: the page does not state it | AD7: 0 | AH7: Yes
A8: 115606C | B8: Bachelor of Advanced Studies (Honours) (Food and Agribusiness) | C8: Bachelor Honours Degree | D8: Undergraduate | E8: Advertised: official page in place | F8: https://www.sydney.edu.au/content/dam/students/documents/honours/bas-flyers/bas-hons-foodag-dom.pdf | G8: https://www.sydney.edu.au/content/dam/students/documents/honours/bas-flyers/bas-hons-foodag-dom.pdf | H8: Read | I8: CRICOS code on page | K8: Not sent to re-link | L8: Filled | M8: Not stated on course page | O8: 0 | Q8: Filled | R8: 6.5 | S8: Central English policy | T8: Central rule applies (value agrees) | V8: Not stated on course page | Y8: 2 | Z8: Yes | AA8: Filled | AB8: on campus | AC8: Filled | AD8: 0 | AH8: Yes
A9: 118538H | B9: Bachelor of Advanced Studies (Honours) (Taronga Wildlife Conservation) | C9: Bachelor Honours Degree | D9: Undergraduate | E9: Page address no longer works | G9: https://www.sydney.edu.au/courses/courses/uc/bachelor-of-advanced-studies-honours-taronga-wildlife-conservation.html | H9: Address no longer works | K9: Finished, no page: every candidate address was refused by the reader or did not | L9: Page found, being read | M9: Page found, being read | O9: 0 | Q9: Filled | R9: 6.5 | S9: Central English policy | T9: Central rule applies (value agrees) | V9: Page found, being read | Y9: 0 | Z9: Yes | AA9: Not stated on course page | AC9: Skipped: no allowed source had a value | AD9: 1
A10: 0102151 | B10: Bachelor of Advanced Studies (Media and Communications) | C10: Bachelor | D10: Undergraduate | E10: Advertised: official page in place | F10: https://www.sydney.edu.au/courses/courses/uc/bachelor-of-advanced-studies-media-and-communications0.html | G10: https://www.sydney.edu.au/courses/courses/uc/bachelor-of-advanced-studies-media-and-communications0.html | H10: Read | I10: Exact title match | K10: Not sent to re-link | L10: Filled | M10: Not stated on course page | O10: 0 | Q10: Filled | R10: 6.5 | S10: Central English policy | T10: Central rule applies (value agrees) | V10: Not stated on course page | Y10: 2 | Z10: Yes | AA10: Filled | AB10: on campus | AD10: 0 | AH10: Yes
A11: 114098D | B11: Bachelor of Advanced Studies (Media and Communications) (Honours) | C11: Bachelor Honours Degree | D11: Undergraduate | E11: Advertised: official page in place | F11: https://www.sydney.edu.au/handbooks/arts/coursework/honours-advanced-studies-media-communications/overview.html | G11: https://www.sydney.edu.au/handbooks/arts/coursework/honours-advanced-studies-media-communications/overview.html | H11: Read | I11: Exact title match | K11: Not sent to re-link | L11: Filled | M11: Not stated on course page | O11: 0 | Q11: Filled | R11: 6.5 | S11: Central English policy | T11: Central rule applies (value agrees) | V11: Not stated on course page | Y11: 2 | Z11: Yes | AA11: Not stated on course page | AC11: Skipped: the page does not state it | AD11: 0 | AH11: Yes
A12: 0102152 | B12: Bachelor of Advanced Studies (Media and Communications) (Honours) | C12: Bachelor Honours Degree | D12: Undergraduate | E12: Advertised: official page in place | F12: https://www.sydney.edu.au/handbooks/arts/coursework/honours-advanced-studies-media-communications/overview.html | G12: https://www.sydney.edu.au/handbooks/arts/coursework/honours-advanced-studies-media-communications/overview.html | H12: Read | I12: Exact title match | K12: Not sent to re-link | L12: Filled | M12: Not stated on course page | O12: 0 | Q12: Filled | R12: 6.5 | S12: Central English policy | T12: Central rule applies (value agrees) | V12: Not stated on course page | Y12: 2 | Z12: Yes | AA12: Not stated on course page | AC12: Skipped: the page does not state it | AD12: 0 | AH12: Yes
A13: 000658B | B13: Bachelor of Agricultural Economics | C13: Bachelor | D13: Undergraduate | E13: No-page record (no page), awaiting review | G13: https://rp-handbooks.sydney.edu.au/handbooks/archive/2016/agriculture/undergraduate/b_agricultural_economics_units_of_study.shtml.html | H13: Not a course page | J13: No page (proposed) | K13: Not sent to re-link | L13: Not stated on course page | M13: Not stated on course page | O13: 0 | Q13: Filled | R13: 6.5 | S13: Central English policy | T13: Central rule applies (value agrees) | V13: Not stated on course page | Y13: 2 | Z13: Yes | AA13: Not stated on course page | AC13: Skipped: taken back: the page read was another course's page | AD13: 1 | AM13: Yes
A14: 111866D | B14: Bachelor of Agricultural Science | C14: Bachelor | D14: Undergraduate | E14: Advertised: official page in place | F14: https://www.sydney.edu.au/courses/courses/uc/bachelor-of-agricultural-science.html | G14: https://www.sydney.edu.au/courses/courses/uc/bachelor-of-agricultural-science.html | H14: Read | I14: Exact title match | K14: Not sent to re-link | L14: Filled | M14: Not stated on course page | O14: 0 | Q14: Filled | R14: 6.5 | S14: Central English policy | T14: Central rule applies (value agrees) | V14: Not stated on course page | Y14: 2 | Z14: Yes | AA14: Filled | AB14: on campus | AD14: 0 | AH14: Yes
A15: 111869A | B15: Bachelor of Agricultural Science Honours | C15: Bachelor Honours Degree | D15: Undergraduate | E15: Advertised: official page in place | F15: https://www.sydney.edu.au/courses/courses/uc/bachelor-of-agricultural-science-honours.html | G15: https://www.sydney.edu.au/courses/courses/uc/bachelor-of-agricultural-science-honours.html | H15: Read | I15: Exact title match | K15: Not sent to re-link | L15: Filled | M15: Not stated on course page | O15: 0 | Q15: Filled | R15: 6.5 | S15: Central English policy | T15: Central rule applies (value agrees) | V15: Not stated on course page | Y15: 2 | Z15: Yes | AA15: Filled | AB15: on campus | AD15: 0 | AH15: Yes
A16: 116443J | B16: Bachelor of Animal and Veterinary Bioscience | C16: Bachelor | D16: Undergraduate | E16: Advertised: official page in place | F16: https://www.sydney.edu.au/courses/courses/uc/bachelor-of-animal-and-veterinary-bioscience.html | G16: https://www.sydney.edu.au/courses/courses/uc/bachelor-of-animal-and-veterinary-bioscience.html | H16: Read | I16: Exact title match | K16: Not sent to re-link | L16: Filled | M16: Not stated on course page | O16: 0 | Q16: Filled | R16: 6.5 | S16: Central English policy | T16: Central rule applies (value agrees) | V16: Not stated on course page | Y16: 2 | Z16: Yes | AA16: Filled | AB16: on campus | AD16: 0 | AH16: Yes
A17: 053423E | B17: Bachelor of Animal and Veterinary Bioscience | C17: Bachelor | D17: Undergraduate | E17: Advertised: official page in place | F17: https://www.sydney.edu.au/courses/courses/uc/bachelor-of-animal-and-veterinary-bioscience.html | G17: https://www.sydney.edu.au/courses/courses/uc/bachelor-of-animal-and-veterinary-bioscience.html | H17: Read | I17: Exact title match | K17: Not sent to re-link | L17: Filled | M17: Not stated on course page | O17: 0 | Q17: Filled | R17: 6.5 | S17: Central English policy | T17: Central rule applies (value agrees) | V17: Not stated on course page | Y17: 2 | Z17: Yes | AA17: Filled | AB17: on campus | AD17: 0 | AH17: Yes
A18: 116442K | B18: Bachelor of Animal and Veterinary Bioscience (Honours) | C18: Bachelor Honours Degree | D18: Undergraduate | E18: Advertised: official page in place | F18: https://www.sydney.edu.au/courses/courses/uc/bachelor-of-animal-and-veterinary-bioscience-honours.html | G18: https://www.sydney.edu.au/courses/courses/uc/bachelor-of-animal-and-veterinary-bioscience-honours.html | H18: Read | I18: Exact title match | K18: Not sent to re-link | L18: Filled | M18: Not stated on course page | O18: 0 | Q18: Filled | R18: 6.5 | S18: Central English policy | T18: Central rule applies (value agrees) | V18: Filled | W18: January, June | X18: Other | Y18: 0 | Z18: Yes | AA18: Filled | AB18: on campus | AD18: 0
A19: 079215K | B19: Bachelor of Applied Science (Diagnostic Radiography) | C19: Bachelor | D19: Undergraduate | E19: Advertised: official page in place | F19: https://www.sydney.edu.au/courses/courses/uc/bachelor-of-applied-science-diagnostic-radiography.html | G19: https://www.sydney.edu.au/courses/courses/uc/bachelor-of-applied-science-diagnostic-radiography.html | H19: Read | I19: Exact title match | K19: Not sent to re-link | L19: Filled | M19: Not stated on course page | O19: 0 | Q19: Filled | R19: 6.5 | S19: Central English policy | T19: Central rule applies (value agrees) | V19: Not stated on course page | Y19: 2 | Z19: Yes | AA19: Filled | AB19: on campus | AD19: 0 | AH19: Yes
A20: 022306M | B20: Bachelor of Applied Science (Exercise and Sport Science) | C20: Bachelor | D20: Undergraduate | E20: Advertised: official page in place | F20: https://www.sydney.edu.au/courses/courses/uc/bachelor-of-applied-science-exercise-and-sport-science0.html | G20: https://www.sydney.edu.au/courses/courses/uc/bachelor-of-applied-science-exercise-and-sport-science0.html | H20: Read | I20: Exact title match | K20: Not sent to re-link | L20: Filled | M20: Not stated on course page | O20: 0 | Q20: Filled | R20: 6.5 | S20: Central English policy | T20: Central rule applies (value agrees) | V20: Not stated on course page | Y20: 2 | Z20: Yes | AA20: Filled | AB20: on campus | AD20: 0 | AH20: Yes
A21: 028770E | B21: Bachelor of Applied Science (Exercise and Sport Science) Honours | C21: Bachelor Honours Degree | D21: Undergraduate | E21: Advertised: official page in place | F21: https://www.sydney.edu.au/courses/courses/uc/bachelor-of-applied-science-exercise-and-sport-science-honours.html | G21: https://www.sydney.edu.au/courses/courses/uc/bachelor-of-applied-science-exercise-and-sport-science-honours.html | H21: Read | I21: Exact title match | K21: Not sent to re-link | L21: Filled | M21: Not stated on course page | O21: 0 | Q21: Filled | R21: 6.5 | S21: Central English policy | T21: Central rule applies (value agrees) | V21: Not stated on course page | Y21: 2 | Z21: Yes | AA21: Filled | AB21: on campus | AD21: 0 | AH21: Yes
A22: 074245M | B22: Bachelor of Applied Science (Exercise Physiology) | C22: Bachelor | D22: Undergraduate | E22: Advertised: official page in place | F22: https://www.sydney.edu.au/courses/courses/uc/bachelor-of-applied-science-exercise-physiology7.html | G22: https://www.sydney.edu.au/courses/courses/uc/bachelor-of-applied-science-exercise-physiology7.html | H22: Read | I22: Exact title match | K22: Not sent to re-link | L22: Filled | M22: Not stated on course page | O22: 0 | Q22: Filled | R22: 6.5 | S22: Central English policy | T22: Central rule applies (value agrees) | V22: Not stated on course page | Y22: 2 | Z22: Yes | AA22: Filled | AB22: on campus | AD22: 0 | AH22: Yes
A23: 088106G | B23: Bachelor of Applied Science (Exercise Physiology) | C23: Bachelor | D23: Undergraduate | E23: Advertised: official page in place | F23: https://www.sydney.edu.au/courses/courses/uc/bachelor-of-applied-science-exercise-physiology7.html | G23: https://www.sydney.edu.au/courses/courses/uc/bachelor-of-applied-science-exercise-physiology7.html | H23: Read | I23: Exact title match | K23: Not sent to re-link | L23: Filled | M23: Not stated on course page | O23: 0 | Q23: Filled | R23: 6.5 | S23: Central English policy | T23: Central rule applies (value agrees) | V23: Not stated on course page | Y23: 2 | Z23: Yes | AA23: Filled | AB23: on campus | AD23: 0 | AH23: Yes
A24: 063849G | B24: Bachelor of Applied Science (Occupational Therapy) | C24: Bachelor | D24: Undergraduate | E24: Advertised: official page in place | F24: https://www.sydney.edu.au/courses/courses/uc/bachelor-of-applied-science-occupational-therapy0.html | G24: https://www.sydney.edu.au/courses/courses/uc/bachelor-of-applied-science-occupational-therapy0.html | H24: Read | I24: Exact title match | K24: Not sent to re-link | L24: Filled | M24: Not stated on course page | O24: 0 | Q24: Filled | R24: 6.5 | S24: Central English policy | T24: Central rule applies (value agrees) | V24: Not stated on course page | Y24: 2 | Z24: Yes | AA24: Filled | AB24: on campus | AD24: 0 | AH24: Yes
A25: 063847J | B25: Bachelor of Applied Science (Physiotherapy) | C25: Bachelor | D25: Undergraduate | E25: Advertised: official page in place | F25: https://www.sydney.edu.au/courses/courses/uc/bachelor-of-applied-science-physiotherapy.html | G25: https://www.sydney.edu.au/courses/courses/uc/bachelor-of-applied-science-physiotherapy.html | H25: Read | I25: Exact title match | K25: Not sent to re-link | L25: Filled | M25: Not stated on course page | O25: 0 | Q25: Filled | R25: 6.5 | S25: Central English policy | T25: Central rule applies (value agrees) | V25: Not stated on course page | Y25: 2 | Z25: Yes | AA25: Filled | AB25: on campus | AD25: 0 | AH25: Yes
A26: 012825D | B26: Bachelor of Applied Science (Speech Pathology) | C26: Bachelor | D26: Undergraduate | E26: Advertised: official page in place | F26: https://www.sydney.edu.au/courses/courses/uc/bachelor-of-applied-science-speech-pathology.html | G26: https://www.sydney.edu.au/courses/courses/uc/bachelor-of-applied-science-speech-pathology.html | H26: Read | I26: Exact title match | K26: Not sent to re-link | L26: Filled | M26: Not stated on course page | O26: 0 | Q26: Filled | R26: 6.5 | S26: Central English policy | T26: Central rule applies (value agrees) | V26: Not stated on course page | Y26: 2 | Z26: Yes | AA26: Filled | AB26: on campus | AD26: 0 | AH26: Yes
A27: 082879K | B27: Bachelor of Architecture and Environments | C27: Bachelor | D27: Undergraduate | E27: Advertised: official page in place | F27: https://www.sydney.edu.au/courses/courses/uc/bachelor-of-architecture-and-environments.html | G27: https://www.sydney.edu.au/courses/courses/uc/bachelor-of-architecture-and-environments.html | H27: Read | I27: Exact title match | K27: Not sent to re-link | L27: Filled | M27: Not stated on course page | O27: 0 | Q27: Filled | R27: 6.5 | S27: Central English policy | T27: Central rule applies (value agrees) | V27: Not stated on course page | Y27: 2 | Z27: Yes | AA27: Filled | AB27: on campus | AD27: 0 | AH27: Yes
