Workbook

Sheet Read me
A1: Canada course data by provider: 2026-11-01
A3: Start: values held on 2026-10-21, the first day recorded for Canada.
A4: Previous: the day before (2026-10-31). Today: 2026-11-01. Each day is recorded at about 6:55 am Melbourne time.
A5: Scope: 52 CA providers with active courses, 3,814 active courses.
A7: Sheets
A8: CA summary: each field across Canada at the start, the previous day and today, with the changes and % filled.
A9: Per provider: one row per provider; for each course field, the number of courses holding it at the start, the previous day and today, the change today and the change since the start. Provider fields show Yes or No.
A10: Long list: the same figures as one row per provider and field, for filtering and pivot tables.
A11: Courses: one row per active course (3,814) with the value held for each course field. An empty field shows why it is not held (for example "— not on the course page" or "— no reader yet"). Values as at 2026-11-01; course states from 2026-10-31 19:47 UTC.
A12: Entry requirements: the entry rules each provider publishes (minimum results, band ladders), active and proposed; course-level entry requirements are in the Courses sheet.
A13: Scholarships: each active scholarship of these providers (99) with its award, dates, audience and source page. Scholarships are held per provider, not per course; the Courses sheet shows how many each provider has.
A14: Toolset use: each tool per provider for the last recorded day and the last 7 days: times used, worked, did not work, scraper credits and AI US$, with a summary by tool at the top. "Worked" means: a correct course page (search, page match), a page read, a field filled, a fee page with fee rows, a scholarship applied.
... A18: A provider with no figure for a day had no active courses recorded that day.

Sheet CA summary
A1: Field | B1: Level | C1: Total | D1: Start | E1: Previous | F1: Today | G1: Change today | H1: Change since start | I1: % start | J1: % today
A2: Official course page | B2: Course | C2: =SUM('Per provider'!C3:C54) -> 3814 | D2: =SUM('Per provider'!D3:D54) -> 2705 | E2: =SUM('Per provider'!E3:E54) -> 2665 | F2: =SUM('Per provider'!F3:F54) -> 2665 | G2: =F2-E2 -> 0 | H2: =F2-D2 -> -40 | I2: =IF(C2=0,0,D2/C2) -> 0.70922916 | J2: =IF(C2=0,0,F2/C2) -> 0.69874148
A3: Study level | B3: Course | C3: =SUM('Per provider'!C3:C54) -> 3814 | D3: =SUM('Per provider'!I3:I54) -> 2701 | E3: =SUM('Per provider'!J3:J54) -> 3814 | F3: =SUM('Per provider'!K3:K54) -> 3814 | G3: =F3-E3 -> 0 | H3: =F3-D3 -> 1113 | I3: =IF(C3=0,0,D3/C3) -> 0.70818039 | J3: =IF(C3=0,0,F3/C3) -> 1
A4: Field of study | B4: Course | C4: =SUM('Per provider'!C3:C54) -> 3814 | D4: =SUM('Per provider'!N3:N54) -> 4624 | E4: =SUM('Per provider'!O3:O54) -> 3774 | F4: =SUM('Per provider'!P3:P54) -> 3774 | G4: =F4-E4 -> 0 | H4: =F4-D4 -> -850 | I4: =IF(C4=0,0,D4/C4) -> 1.2123755 | J4: =IF(C4=0,0,F4/C4) -> 0.98951232
A5: Duration | B5: Course | C5: =SUM('Per provider'!C3:C54) -> 3814 | D5: =SUM('Per provider'!S3:S54) -> 1527 | E5: =SUM('Per provider'!T3:T54) -> 1324 | F5: =SUM('Per provider'!U3:U54) -> 1324 | G5: =F5-E5 -> 0 | H5: =F5-D5 -> -203 | I5: =IF(C5=0,0,D5/C5) -> 0.40036707 | J5: =IF(C5=0,0,F5/C5) -> 0.34714211
A6: Delivery mode | B6: Course | C6: =SUM('Per provider'!C3:C54) -> 3814 | D6: =SUM('Per provider'!X3:X54) -> 2939 | E6: =SUM('Per provider'!Y3:Y54) -> 2298 | F6: =SUM('Per provider'!Z3:Z54) -> 2298 | G6: =F6-E6 -> 0 | H6: =F6-D6 -> -641 | I6: =IF(C6=0,0,D6/C6) -> 0.77058207 | J6: =IF(C6=0,0,F6/C6) -> 0.60251704
A7: Campus linked | B7: Course | C7: =SUM('Per provider'!C3:C54) -> 3814 | D7: =SUM('Per provider'!AC3:AC54) -> 2403 | E7: =SUM('Per provider'!AD3:AD54) -> 2102 | F7: =SUM('Per provider'!AE3:AE54) -> 2105 | G7: =F7-E7 -> 3 | H7: =F7-D7 -> -298 | I7: =IF(C7=0,0,D7/C7) -> 0.63004719 | J7: =IF(C7=0,0,F7/C7) -> 0.551914
A8: Campus city | B8: Course | C8: =SUM('Per provider'!C3:C54) -> 3814 | D8: =SUM('Per provider'!AH3:AH54) -> 1874 | E8: =SUM('Per provider'!AI3:AI54) -> 1545 | F8: =SUM('Per provider'!AJ3:AJ54) -> 1545 | G8: =F8-E8 -> 0 | H8: =F8-D8 -> -329 | I8: =IF(C8=0,0,D8/C8) -> 0.49134767 | J8: =IF(C8=0,0,F8/C8) -> 0.40508652
A9: Open to international students | B9: Course | C9: =SUM('Per provider'!C3:C54) -> 3814 | D9: =SUM('Per provider'!AM3:AM54) -> 4723 | E9: =SUM('Per provider'!AN3:AN54) -> 3814 | F9: =SUM('Per provider'!AO3:AO54) -> 3814 | G9: =F9-E9 -> 0 | H9: =F9-D9 -> -909 | I9: =IF(C9=0,0,D9/C9) -> 1.2383325 | J9: =IF(C9=0,0,F9/C9) -> 1
A10: Tuition fee | B10: Course | C10: =SUM('Per provider'!C3:C54) -> 3814 | D10: =SUM('Per provider'!AR3:AR54) -> 419 | E10: =SUM('Per provider'!AS3:AS54) -> 683 | F10: =SUM('Per provider'!AT3:AT54) -> 683 | G10: =F10-E10 -> 0 | H10: =F10-D10 -> 264 | I10: =IF(C10=0,0,D10/C10) -> 0.10985842 | J10: =IF(C10=0,0,F10/C10) -> 0.17907708
A11: Intakes / start dates | B11: Course | C11: =SUM('Per provider'!C3:C54) -> 3814 | D11: =SUM('Per provider'!AW3:AW54) -> 1049 | E11: =SUM('Per provider'!AX3:AX54) -> 1613 | F11: =SUM('Per provider'!AY3:AY54) -> 1613 | G11: =F11-E11 -> 0 | H11: =F11-D11 -> 564 | I11: =IF(C11=0,0,D11/C11) -> 0.27503933 | J11: =IF(C11=0,0,F11/C11) -> 0.42291557
A12: Application deadline | B12: Course | C12: =SUM('Per provider'!C3:C54) -> 3814 | D12: =SUM('Per provider'!BB3:BB54) -> 0 | E12: =SUM('Per provider'!BC3:BC54) -> 0 | F12: =SUM('Per provider'!BD3:BD54) -> 0 | G12: =F12-E12 -> 0 | H12: =F12-D12 -> 0 | I12: =IF(C12=0,0,D12/C12) -> 0 | J12: =IF(C12=0,0,F12/C12) -> 0
A13: English requirements | B13: Course | C13: =SUM('Per provider'!C3:C54) -> 3814 | D13: =SUM('Per provider'!BG3:BG54) -> 1789 | E13: =SUM('Per provider'!BH3:BH54) -> 2010 | F13: =SUM('Per provider'!BI3:BI54) -> 2010 | G13: =F13-E13 -> 0 | H13: =F13-D13 -> 221 | I13: =IF(C13=0,0,D13/C13) -> 0.46906135 | J13: =IF(C13=0,0,F13/C13) -> 0.52700577
A14: Academic entry requirements | B14: Course | C14: =SUM('Per provider'!C3:C54) -> 3814 | D14: =SUM('Per provider'!BL3:BL54) -> 0 | E14: =SUM('Per provider'!BM3:BM54) -> 0 | F14: =SUM('Per provider'!BN3:BN54) -> 0 | G14: =F14-E14 -> 0 | H14: =F14-D14 -> 0 | I14: =IF(C14=0,0,D14/C14) -> 0 | J14: =IF(C14=0,0,F14/C14) -> 0
A15: Course description | B15: Course | C15: =SUM('Per provider'!C3:C54) -> 3814 | D15: =SUM('Per provider'!BQ3:BQ54) -> 0 | E15: =SUM('Per provider'!BR3:BR54) -> 0 | F15: =SUM('Per provider'!BS3:BS54) -> 0 | G15: =F15-E15 -> 0 | H15: =F15-D15 -> 0 | I15: =IF(C15=0,0,D15/C15) -> 0 | J15: =IF(C15=0,0,F15/C15) -> 0
A16: Website | B16: Provider | C16: =COUNTA('Per provider'!A3:A54) -> 52 | D16: =COUNTIF('Per provider'!BV3:BV54,"Yes") -> 52 | E16: =COUNTIF('Per provider'!BW3:BW54,"Yes") -> 52 | F16: =COUNTIF('Per provider'!BX3:BX54,"Yes") -> 52 | G16: =F16-E16 -> 0 | H16: =F16-D16 -> 0 | I16: =IF(C16=0,0,D16/C16) -> 1 | J16: =IF(C16=0,0,F16/C16) -> 1
A17: Street address | B17: Provider | C17: =COUNTA('Per provider'!A3:A54) -> 52 | D17: =COUNTIF('Per provider'!BY3:BY54,"Yes") -> 17 | E17: =COUNTIF('Per provider'!BZ3:BZ54,"Yes") -> 17 | F17: =COUNTIF('Per provider'!CA3:CA54,"Yes") -> 17 | G17: =F17-E17 -> 0 | H17: =F17-D17 -> 0 | I17: =IF(C17=0,0,D17/C17) -> 0.32692308 | J17: =IF(C17=0,0,F17/C17) -> 0.32692308
A18: Campuses | B18: Provider | C18: =COUNTA('Per provider'!A3:A54) -> 52 | D18: =COUNTIF('Per provider'!CB3:CB54,"Yes") -> 41 | E18: =COUNTIF('Per provider'!CC3:CC54,"Yes") -> 45 | F18: =COUNTIF('Per provider'!CD3:CD54,"Yes") -> 45 | G18: =F18-E18 -> 0 | H18: =F18-D18 -> 4 | I18: =IF(C18=0,0,D18/C18) -> 0.78846154 | J18: =IF(C18=0,0,F18/C18) -> 0.86538462
A19: Institution type | B19: Provider | C19: =COUNTA('Per provider'!A3:A54) -> 52 | D19: =COUNTIF('Per provider'!CE3:CE54,"Yes") -> 0 | E19: =COUNTIF('Per provider'!CF3:CF54,"Yes") -> 0 | F19: =COUNTIF('Per provider'!CG3:CG54,"Yes") -> 0 | G19: =F19-E19 -> 0 | H19: =F19-D19 -> 0 | I19: =IF(C19=0,0,D19/C19) -> 0 | J19: =IF(C19=0,0,F19/C19) -> 0
A20: Enrols international students | B20: Provider | C20: =COUNTA('Per provider'!A3:A54) -> 52 | D20: =COUNTIF('Per provider'!CH3:CH54,"Yes") -> 52 | E20: =COUNTIF('Per provider'!CI3:CI54,"Yes") -> 52 | F20: =COUNTIF('Per provider'!CJ3:CJ54,"Yes") -> 52 | G20: =F20-E20 -> 0 | H20: =F20-D20 -> 0 | I20: =IF(C20=0,0,D20/C20) -> 1 | J20: =IF(C20=0,0,F20/C20) -> 1
A21: Logo | B21: Provider | C21: =COUNTA('Per provider'!A3:A54) -> 52 | D21: =COUNTIF('Per provider'!CK3:CK54,"Yes") -> 45 | E21: =COUNTIF('Per provider'!CL3:CL54,"Yes") -> 45 | F21: =COUNTIF('Per provider'!CM3:CM54,"Yes") -> 45 | G21: =F21-E21 -> 0 | H21: =F21-D21 -> 0 | I21: =IF(C21=0,0,D21/C21) -> 0.86538462 | J21: =IF(C21=0,0,F21/C21) -> 0.86538462
A22: Phone or email | B22: Provider | C22: =COUNTA('Per provider'!A3:A54) -> 52 | D22: =COUNTIF('Per provider'!CN3:CN54,"Yes") -> 41 | E22: =COUNTIF('Per provider'!CO3:CO54,"Yes") -> 41 | F22: =COUNTIF('Per provider'!CP3:CP54,"Yes") -> 41 | G22: =F22-E22 -> 0 | H22: =F22-D22 -> 0 | I22: =IF(C22=0,0,D22/C22) -> 0.78846154 | J22: =IF(C22=0,0,F22/C22) -> 0.78846154
A23: Scholarships | B23: Provider | C23: =COUNTA('Per provider'!A3:A54) -> 52 | D23: =COUNTIF('Per provider'!CQ3:CQ54,"Yes") -> 11 | E23: =COUNTIF('Per provider'!CR3:CR54,"Yes") -> 13 | F23: =COUNTIF('Per provider'!CS3:CS54,"Yes") -> 13 | G23: =F23-E23 -> 0 | H23: =F23-D23 -> 2 | I23: =IF(C23=0,0,D23/C23) -> 0.21153846 | J23: =IF(C23=0,0,F23/C23) -> 0.25
A24: Description | B24: Provider | C24: =COUNTA('Per provider'!A3:A54) -> 52 | D24: =COUNTIF('Per provider'!CT3:CT54,"Yes") -> 0 | E24: =COUNTIF('Per provider'!CU3:CU54,"Yes") -> 0 | F24: =COUNTIF('Per provider'!CV3:CV54,"Yes") -> 0 | G24: =F24-E24 -> 0 | H24: =F24-D24 -> 0 | I24: =IF(C24=0,0,D24/C24) -> 0 | J24: =IF(C24=0,0,F24/C24) -> 0
A26: Course fields count courses; provider fields count providers. Figures come from the Per provider sheet.

Sheet Per provider
A1: Provider | B1: Website | C1: Courses | D1: Official course page | I1: Study level | N1: Field of study | S1: Duration | X1: Delivery mode | AC1: Campus linked | AH1: Campus city | AM1: Open to international students | AR1: Tuition fee | AW1: Intakes / start dates | BB1: Application deadline | BG1: English requirements | BL1: Academic entry requirements | BQ1: Course description | BV1: Website | BY1: Street address | CB1: Campuses | CE1: Institution type | CH1: Enrols international students | CK1: Logo | CN1: Phone or email | CQ1: Scholarships | CT1: Description
D2: Start | E2: Previous | F2: Today | G2: Change today | H2: Change since start | I2: Start | J2: Previous | K2: Today | L2: Change today | M2: Change since start | N2: Start | O2: Previous | P2: Today | Q2: Change today | R2: Change since start | S2: Start | T2: Previous | U2: Today | V2: Change today | W2: Change since start | X2: Start | Y2: Previous | Z2: Today | AA2: Change today | AB2: Change since start | AC2: Start | AD2: Previous | AE2: Today | AF2: Change today | AG2: Change since start | AH2: Start | AI2: Previous | AJ2: Today | AK2: Change today | AL2: Change since start | AM2: Start | AN2: Previous | AO2: Today | AP2: Change today | AQ2: Change since start | AR2: Start | AS2: Previous | AT2: Today | AU2: Change today | AV2: Change since start | AW2: Start | AX2: Previous | AY2: Today | AZ2: Change today | BA2: Change since start | BB2: Start | BC2: Previous | BD2: Today | BE2: Change today | BF2: Change since start | BG2: Start | BH2: Previous | BI2: Today | BJ2: Change today | BK2: Change since start | BL2: Start | BM2: Previous | BN2: Today | BO2: Change today | BP2: Change since start | BQ2: Start | BR2: Previous | BS2: Today | BT2: Change today | BU2: Change since start | BV2: Start | BW2: Previous | BX2: Today | BY2: Start | BZ2: Previous | CA2: Today | CB2: Start | CC2: Previous | CD2: Today | CE2: Start | CF2: Previous | CG2: Today | CH2: Start | CI2: Previous | CJ2: Today | CK2: Start | CL2: Previous | CM2: Today | CN2: Start | CO2: Previous | CP2: Today | CQ2: Start | CR2: Previous | CS2: Today | CT2: Start | CU2: Previous | CV2: Today
A3: University of British Columbia (UBC) | B3: https://www.ubc.ca | C3: 575 | D3: 342 | E3: 343 | F3: 343 | G3: =F3-E3 -> 0 | H3: =F3-D3 -> 1 | I3: 575 | J3: 575 | K3: 575 | L3: =K3-J3 -> 0 | M3: =K3-I3 -> 0 | N3: 569 | O3: 570 | P3: 570 | Q3: =P3-O3 -> 0 | R3: =P3-N3 -> 1 | S3: 270 | T3: 189 | U3: 189 | V3: =U3-T3 -> 0 | W3: =U3-S3 -> -81 | X3: 441 | Y3: 316 | Z3: 316 | AA3: =Z3-Y3 -> 0 | AB3: =Z3-X3 -> -125 | AC3: 465 | AD3: 314 | AE3: 314 | AF3: =AE3-AD3 -> 0 | AG3: =AE3-AC3 -> -151 | AH3: 465 | AI3: 314 | AJ3: 314 | AK3: =AJ3-AI3 -> 0 | AL3: =AJ3-AH3 -> -151 | AM3: 575 | AN3: 575 | AO3: 575 | AP3: =AO3-AN3 -> 0 | AQ3: =AO3-AM3 -> 0 | AR3: 275 | AS3: 275 | AT3: 275 | AU3: =AT3-AS3 -> 0 | AV3: =AT3-AR3 -> 0 | AW3: 250 | AX3: 252 | AY3: 252 | AZ3: =AY3-AX3 -> 0 | BA3: =AY3-AW3 -> 2 | BB3: 0 | BC3: 0 | BD3: 0 | BE3: =BD3-BC3 -> 0 | BF3: =BD3-BB3 -> 0 | BG3: 539 | BH3: 539 | BI3: 539 | BJ3: =BI3-BH3 -> 0 | BK3: =BI3-BG3 -> 0 | BL3: 0 | BM3: 0 | BN3: 0 | BO3: =BN3-BM3 -> 0 | BP3: =BN3-BL3 -> 0 | BQ3: 0 | BR3: 0 | BS3: 0 | BT3: =BS3-BR3 -> 0 | BU3: =BS3-BQ3 -> 0 | BV3: Yes | BW3: Yes | BX3: Yes | BY3: Yes | BZ3: Yes | CA3: Yes | CB3: Yes | CC3: Yes | CD3: Yes | CE3: No | CF3: No | CG3: No | CH3: Yes | CI3: Yes | CJ3: Yes | CK3: Yes | CL3: Yes | CM3: Yes | CN3: No | CO3: No | CP3: No | CQ3: Yes | CR3: Yes | CS3: Yes | CT3: No | CU3: No | CV3: No
A4: University of Alberta | B4: https://www.ualberta.ca | C4: 379 | D4: 222 | E4: 222 | F4: 222 | G4: =F4-E4 -> 0 | H4: =F4-D4 -> 0 | I4: 379 | J4: 379 | K4: 379 | L4: =K4-J4 -> 0 | M4: =K4-I4 -> 0 | N4: 371 | O4: 372 | P4: 372 | Q4: =P4-O4 -> 0 | R4: =P4-N4 -> 1 | S4: 17 | T4: 9 | U4: 9 | V4: =U4-T4 -> 0 | W4: =U4-S4 -> -8 | X4: 134 | Y4: 91 | Z4: 91 | AA4: =Z4-Y4 -> 0 | AB4: =Z4-X4 -> -43 | AC4: 172 | AD4: 130 | AE4: 130 | AF4: =AE4-AD4 -> 0 | AG4: =AE4-AC4 -> -42 | AH4: 172 | AI4: 130 | AJ4: 130 | AK4: =AJ4-AI4 -> 0 | AL4: =AJ4-AH4 -> -42 | AM4: 379 | AN4: 379 | AO4: 379 | AP4: =AO4-AN4 -> 0 | AQ4: =AO4-AM4 -> 0 | AR4: 0 | AS4: 0 | AT4: 0 | AU4: =AT4-AS4 -> 0 | AV4: =AT4-AR4 -> 0 | AW4: 1 | AX4: 1 | AY4: 1 | AZ4: =AY4-AX4 -> 0 | BA4: =AY4-AW4 -> 0 | BB4: 0 | BC4: 0 | BD4: 0 | BE4: =BD4-BC4 -> 0 | BF4: =BD4-BB4 -> 0 | BG4: 337 | BH4: 337 | BI4: 337 | BJ4: =BI4-BH4 -> 0 | BK4: =BI4-BG4 -> 0 | BL4: 0 | BM4: 0 | BN4: 0 | BO4: =BN4-BM4 -> 0 | BP4: =BN4-BL4 -> 0 | BQ4: 0 | BR4: 0 | BS4: 0 | BT4: =BS4-BR4 -> 0 | BU4: =BS4-BQ4 -> 0 | BV4: Yes | BW4: Yes | BX4: Yes | BY4: No | BZ4: No | CA4: No | CB4: Yes | CC4: Yes | CD4: Yes | CE4: No | CF4: No | CG4: No | CH4: Yes | CI4: Yes | CJ4: Yes | CK4: Yes | CL4: Yes | CM4: Yes | CN4: Yes | CO4: Yes | CP4: Yes | CQ4: No | CR4: No | CS4: No | CT4: No | CU4: No | CV4: No
A5: Conestoga College | B5: https://www.conestogac.on.ca | C5: 270 | D5: 270 | E5: 264 | F5: 264 | G5: =F5-E5 -> 0 | H5: =F5-D5 -> -6 | I5: 34 | J5: 270 | K5: 270 | L5: =K5-J5 -> 0 | M5: =K5-I5 -> 236 | N5: 312 | O5: 270 | P5: 270 | Q5: =P5-O5 -> 0 | R5: =P5-N5 -> -42 | S5: 157 | T5: 186 | U5: 186 | V5: =U5-T5 -> 0 | W5: =U5-S5 -> 29 | X5: 275 | Y5: 262 | Z5: 262 | AA5: =Z5-Y5 -> 0 | AB5: =Z5-X5 -> -13 | AC5: 131 | AD5: 124 | AE5: 124 | AF5: =AE5-AD5 -> 0 | AG5: =AE5-AC5 -> -7 | AH5: 131 | AI5: 124 | AJ5: 124 | AK5: =AJ5-AI5 -> 0 | AL5: =AJ5-AH5 -> -7 | AM5: 315 | AN5: 270 | AO5: 270 | AP5: =AO5-AN5 -> 0 | AQ5: =AO5-AM5 -> -45 | AR5: 0 | AS5: 16 | AT5: 16 | AU5: =AT5-AS5 -> 0 | AV5: =AT5-AR5 -> 16 | AW5: 0 | AX5: 132 | AY5: 132 | AZ5: =AY5-AX5 -> 0 | BA5: =AY5-AW5 -> 132 | BB5: 0 | BC5: 0 | BD5: 0 | BE5: =BD5-BC5 -> 0 | BF5: =BD5-BB5 -> 0 | BG5: 0 | BH5: 0 | BI5: 0 | BJ5: =BI5-BH5 -> 0 | BK5: =BI5-BG5 -> 0 | BL5: 0 | BM5: 0 | BN5: 0 | BO5: =BN5-BM5 -> 0 | BP5: =BN5-BL5 -> 0 | BQ5: 0 | BR5: 0 | BS5: 0 | BT5: =BS5-BR5 -> 0 | BU5: =BS5-BQ5 -> 0 | BV5: Yes | BW5: Yes | BX5: Yes | BY5: Yes | BZ5: Yes | CA5: Yes | CB5: Yes | CC5: Yes | CD5: Yes | CE5: No | CF5: No | CG5: No | CH5: Yes | CI5: Yes | CJ5: Yes | CK5: Yes | CL5: Yes | CM5: Yes | CN5: Yes | CO5: Yes | CP5: Yes | CQ5: No | CR5: No | CS5: No | CT5: No | CU5: No | CV5: No
A6: University of Victoria | B6: https://www.uvic.ca | C6: 234 | D6: 139 | E6: 141 | F6: 141 | G6: =F6-E6 -> 0 | H6: =F6-D6 -> 2 | I6: 234 | J6: 234 | K6: 234 | L6: =K6-J6 -> 0 | M6: =K6-I6 -> 0 | N6: 227 | O6: 227 | P6: 227 | Q6: =P6-O6 -> 0 | R6: =P6-N6 -> 0 | S6: 112 | T6: 101 | U6: 101 | V6: =U6-T6 -> 0 | W6: =U6-S6 -> -11 | X6: 132 | Y6: 116 | Z6: 116 | AA6: =Z6-Y6 -> 0 | AB6: =Z6-X6 -> -16 | AC6: 105 | AD6: 98 | AE6: 98 | AF6: =AE6-AD6 -> 0 | AG6: =AE6-AC6 -> -7 | AH6: 105 | AI6: 98 | AJ6: 98 | AK6: =AJ6-AI6 -> 0 | AL6: =AJ6-AH6 -> -7 | AM6: 234 | AN6: 234 | AO6: 234 | AP6: =AO6-AN6 -> 0 | AQ6: =AO6-AM6 -> 0 | AR6: 1 | AS6: 2 | AT6: 2 | AU6: =AT6-AS6 -> 0 | AV6: =AT6-AR6 -> 1 | AW6: 95 | AX6: 96 | AY6: 96 | AZ6: =AY6-AX6 -> 0 | BA6: =AY6-AW6 -> 1 | BB6: 0 | BC6: 0 | BD6: 0 | BE6: =BD6-BC6 -> 0 | BF6: =BD6-BB6 -> 0 | BG6: 193 | BH6: 193 | BI6: 193 | BJ6: =BI6-BH6 -> 0 | BK6: =BI6-BG6 -> 0 | BL6: 0 | BM6: 0 | BN6: 0 | BO6: =BN6-BM6 -> 0 | BP6: =BN6-BL6 -> 0 | BQ6: 0 | BR6: 0 | BS6: 0 | BT6: =BS6-BR6 -> 0 | BU6: =BS6-BQ6 -> 0 | BV6: Yes | BW6: Yes | BX6: Yes | BY6: Yes | BZ6: Yes | CA6: Yes | CB6: Yes | CC6: Yes | CD6: Yes | CE6: No | CF6: No | CG6: No | CH6: Yes | CI6: Yes | CJ6: Yes | CK6: Yes | CL6: Yes | CM6: Yes | CN6: Yes | CO6: Yes | CP6: Yes | CQ6: No | CR6: Yes | CS6: Yes | CT6: No | CU6: No | CV6: No
A7: Simon Fraser University (SFU) | B7: https://www.sfu.ca | C7: 208 | D7: 153 | E7: 153 | F7: 153 | G7: =F7-E7 -> 0 | H7: =F7-D7 -> 0 | I7: 208 | J7: 208 | K7: 208 | L7: =K7-J7 -> 0 | M7: =K7-I7 -> 0 | N7: 208 | O7: 208 | P7: 208 | Q7: =P7-O7 -> 0 | R7: =P7-N7 -> 0 | S7: 53 | T7: 43 | U7: 43 | V7: =U7-T7 -> 0 | W7: =U7-S7 -> -10 | X7: 103 | Y7: 77 | Z7: 77 | AA7: =Z7-Y7 -> 0 | AB7: =Z7-X7 -> -26 | AC7: 75 | AD7: 72 | AE7: 72 | AF7: =AE7-AD7 -> 0 | AG7: =AE7-AC7 -> -3 | AH7: 75 | AI7: 72 | AJ7: 72 | AK7: =AJ7-AI7 -> 0 | AL7: =AJ7-AH7 -> -3 | AM7: 208 | AN7: 208 | AO7: 208 | AP7: =AO7-AN7 -> 0 | AQ7: =AO7-AM7 -> 0 | AR7: 0 | AS7: 4 | AT7: 4 | AU7: =AT7-AS7 -> 0 | AV7: =AT7-AR7 -> 4 | AW7: 40 | AX7: 68 | AY7: 68 | AZ7: =AY7-AX7 -> 0 | BA7: =AY7-AW7 -> 28 | BB7: 0 | BC7: 0 | BD7: 0 | BE7: =BD7-BC7 -> 0 | BF7: =BD7-BB7 -> 0 | BG7: 0 | BH7: 74 | BI7: 74 | BJ7: =BI7-BH7 -> 0 | BK7: =BI7-BG7 -> 74 | BL7: 0 | BM7: 0 | BN7: 0 | BO7: =BN7-BM7 -> 0 | BP7: =BN7-BL7 -> 0 | BQ7: 0 | BR7: 0 | BS7: 0 | BT7: =BS7-BR7 -> 0 | BU7: =BS7-BQ7 -> 0 | BV7: Yes | BW7: Yes | BX7: Yes | BY7: No | BZ7: No | CA7: No | CB7: Yes | CC7: Yes | CD7: Yes | CE7: No | CF7: No | CG7: No | CH7: Yes | CI7: Yes | CJ7: Yes | CK7: Yes | CL7: Yes | CM7: Yes | CN7: Yes | CO7: Yes | CP7: Yes | CQ7: Yes | CR7: Yes | CS7: Yes | CT7: No | CU7: No | CV7: No
A8: University of Lethbridge | B8: https://www.ulethbridge.ca | C8: 199 | D8: 164 | E8: 164 | F8: 164 | G8: =F8-E8 -> 0 | H8: =F8-D8 -> 0 | I8: 199 | J8: 199 | K8: 199 | L8: =K8-J8 -> 0 | M8: =K8-I8 -> 0 | N8: 196 | O8: 196 | P8: 196 | Q8: =P8-O8 -> 0 | R8: =P8-N8 -> 0 | S8: 76 | T8: 88 | U8: 88 | V8: =U8-T8 -> 0 | W8: =U8-S8 -> 12 | X8: 160 | Y8: 174 | Z8: 174 | AA8: =Z8-Y8 -> 0 | AB8: =Z8-X8 -> 14 | AC8: 159 | AD8: 173 | AE8: 173 | AF8: =AE8-AD8 -> 0 | AG8: =AE8-AC8 -> 14 | AH8: 159 | AI8: 173 | AJ8: 173 | AK8: =AJ8-AI8 -> 0 | AL8: =AJ8-AH8 -> 14 | AM8: 199 | AN8: 199 | AO8: 199 | AP8: =AO8-AN8 -> 0 | AQ8: =AO8-AM8 -> 0 | AR8: 0 | AS8: 0 | AT8: 0 | AU8: =AT8-AS8 -> 0 | AV8: =AT8-AR8 -> 0 | AW8: 155 | AX8: 169 | AY8: 169 | AZ8: =AY8-AX8 -> 0 | BA8: =AY8-AW8 -> 14 | BB8: 0 | BC8: 0 | BD8: 0 | BE8: =BD8-BC8 -> 0 | BF8: =BD8-BB8 -> 0 | BG8: 184 | BH8: 184 | BI8: 184 | BJ8: =BI8-BH8 -> 0 | BK8: =BI8-BG8 -> 0 | BL8: 0 | BM8: 0 | BN8: 0 | BO8: =BN8-BM8 -> 0 | BP8: =BN8-BL8 -> 0 | BQ8: 0 | BR8: 0 | BS8: 0 | BT8: =BS8-BR8 -> 0 | BU8: =BS8-BQ8 -> 0 | BV8: Yes | BW8: Yes | BX8: Yes | BY8: Yes | BZ8: Yes | CA8: Yes | CB8: Yes | CC8: Yes | CD8: Yes | CE8: No | CF8: No | CG8: No | CH8: Yes | CI8: Yes | CJ8: Yes | CK8: Yes | CL8: Yes | CM8: Yes | CN8: Yes | CO8: Yes | CP8: Yes | CQ8: Yes | CR8: Yes | CS8: Yes | CT8: No | CU8: No | CV8: No
A9: University of Calgary | B9: https://www.ucalgary.ca | C9: 179 | D9: 33 | E9: 33 | F9: 33 | G9: =F9-E9 -> 0 | H9: =F9-D9 -> 0 | I9: 179 | J9: 179 | K9: 179 | L9: =K9-J9 -> 0 | M9: =K9-I9 -> 0 | N9: 178 | O9: 179 | P9: 179 | Q9: =P9-O9 -> 0 | R9: =P9-N9 -> 1 | S9: 25 | T9: 3 | U9: 3 | V9: =U9-T9 -> 0 | W9: =U9-S9 -> -22 | X9: 65 | Y9: 11 | Z9: 11 | AA9: =Z9-Y9 -> 0 | AB9: =Z9-X9 -> -54 | AC9: 73 | AD9: 13 | AE9: 13 | AF9: =AE9-AD9 -> 0 | AG9: =AE9-AC9 -> -60 | AH9: 73 | AI9: 13 | AJ9: 13 | AK9: =AJ9-AI9 -> 0 | AL9: =AJ9-AH9 -> -60 | AM9: 179 | AN9: 179 | AO9: 179 | AP9: =AO9-AN9 -> 0 | AQ9: =AO9-AM9 -> 0 | AR9: 0 | AS9: 1 | AT9: 1 | AU9: =AT9-AS9 -> 0 | AV9: =AT9-AR9 -> 1 | AW9: 3 | AX9: 5 | AY9: 5 | AZ9: =AY9-AX9 -> 0 | BA9: =AY9-AW9 -> 2 | BB9: 0 | BC9: 0 | BD9: 0 | BE9: =BD9-BC9 -> 0 | BF9: =BD9-BB9 -> 0 | BG9: 60 | BH9: 60 | BI9: 60 | BJ9: =BI9-BH9 -> 0 | BK9: =BI9-BG9 -> 0 | BL9: 0 | BM9: 0 | BN9: 0 | BO9: =BN9-BM9 -> 0 | BP9: =BN9-BL9 -> 0 | BQ9: 0 | BR9: 0 | BS9: 0 | BT9: =BS9-BR9 -> 0 | BU9: =BS9-BQ9 -> 0 | BV9: Yes | BW9: Yes | BX9: Yes | BY9: No | BZ9: No | CA9: No | CB9: Yes | CC9: Yes | CD9: Yes | CE9: No | CF9: No | CG9: No | CH9: Yes | CI9: Yes | CJ9: Yes | CK9: Yes | CL9: Yes | CM9: Yes | CN9: Yes | CO9: Yes | CP9: Yes | CQ9: Yes | CR9: Yes | CS9: Yes | CT9: No | CU9: No | CV9: No
A10: Durham College | B10: https://durhamcollege.ca | C10: 144 | D10: 142 | E10: 138 | F10: 138 | G10: =F10-E10 -> 0 | H10: =F10-D10 -> -4 | I10: 36 | J10: 144 | K10: 144 | L10: =K10-J10 -> 0 | M10: =K10-I10 -> 108 | N10: 156 | O10: 144 | P10: 144 | Q10: =P10-O10 -> 0 | R10: =P10-N10 -> -12 | S10: 12 | T10: 12 | U10: 12 | V10: =U10-T10 -> 0 | W10: =U10-S10 -> 0 | X10: 150 | Y10: 137 | Z10: 137 | AA10: =Z10-Y10 -> 0 | AB10: =Z10-X10 -> -13 | AC10: 81 | AD10: 108 | AE10: 108 | AF10: =AE10-AD10 -> 0 | AG10: =AE10-AC10 -> 27 | AH10: 2 | AI10: 38 | AJ10: 38 | AK10: =AJ10-AI10 -> 0 | AL10: =AJ10-AH10 -> 36 | AM10: 158 | AN10: 144 | AO10: 144 | AP10: =AO10-AN10 -> 0 | AQ10: =AO10-AM10 -> -14 | AR10: 0 | AS10: 0 | AT10: 0 | AU10: =AT10-AS10 -> 0 | AV10: =AT10-AR10 -> 0 | AW10: 136 | AX10: 137 | AY10: 137 | AZ10: =AY10-AX10 -> 0 | BA10: =AY10-AW10 -> 1 | BB10: 0 | BC10: 0 | BD10: 0 | BE10: =BD10-BC10 -> 0 | BF10: =BD10-BB10 -> 0 | BG10: 30 | BH10: 32 | BI10: 32 | BJ10: =BI10-BH10 -> 0 | BK10: =BI10-BG10 -> 2 | BL10: 0 | BM10: 0 | BN10: 0 | BO10: =BN10-BM10 -> 0 | BP10: =BN10-BL10 -> 0 | BQ10: 0 | BR10: 0 | BS10: 0 | BT10: =BS10-BR10 -> 0 | BU10: =BS10-BQ10 -> 0 | BV10: Yes | BW10: Yes | BX10: Yes | BY10: No | BZ10: No | CA10: No | CB10: Yes | CC10: Yes | CD10: Yes | CE10: No | CF10: No | CG10: No | CH10: Yes | CI10: Yes | CJ10: Yes | CK10: Yes | CL10: Yes | CM10: Yes | CN10: Yes | CO10: Yes | CP10: Yes | CQ10: No | CR10: No | CS10: No | CT10: No | CU10: No | CV10: No
A11: College of the North Atlantic | B11: https://www.cna.nl.ca | C11: 105 | D11: 59 | E11: 51 | F11: 51 | G11: =F11-E11 -> 0 | H11: =F11-D11 -> -8 | I11: 8 | J11: 105 | K11: 105 | L11: =K11-J11 -> 0 | M11: =K11-I11 -> 97 | N11: 114 | O11: 103 | P11: 103 | Q11: =P11-O11 -> 0 | R11: =P11-N11 -> -11 | S11: 32 | T11: 27 | U11: 27 | V11: =U11-T11 -> 0 | W11: =U11-S11 -> -5 | X11: 117 | Y11: 105 | Z11: 105 | AA11: =Z11-Y11 -> 0 | AB11: =Z11-X11 -> -12 | AC11: 0 | AD11: 87 | AE11: 87 | AF11: =AE11-AD11 -> 0 | AG11: =AE11-AC11 -> 87 | AH11: 0 | AI11: 0 | AJ11: 0 | AK11: =AJ11-AI11 -> 0 | AL11: =AJ11-AH11 -> 0 | AM11: 117 | AN11: 105 | AO11: 105 | AP11: =AO11-AN11 -> 0 | AQ11: =AO11-AM11 -> -12 | AR11: 0 | AS11: 35 | AT11: 35 | AU11: =AT11-AS11 -> 0 | AV11: =AT11-AR11 -> 35 | AW11: 0 | AX11: 49 | AY11: 49 | AZ11: =AY11-AX11 -> 0 | BA11: =AY11-AW11 -> 49 | BB11: 0 | BC11: 0 | BD11: 0 | BE11: =BD11-BC11 -> 0 | BF11: =BD11-BB11 -> 0 | BG11: 7 | BH11: 7 | BI11: 7 | BJ11: =BI11-BH11 -> 0 | BK11: =BI11-BG11 -> 0 | BL11: 0 | BM11: 0 | BN11: 0 | BO11: =BN11-BM11 -> 0 | BP11: =BN11-BL11 -> 0 | BQ11: 0 | BR11: 0 | BS11: 0 | BT11: =BS11-BR11 -> 0 | BU11: =BS11-BQ11 -> 0 | BV11: Yes | BW11: Yes | BX11: Yes | BY11: No | BZ11: No | CA11: No | CB11: No | CC11: Yes | CD11: Yes | CE11: No | CF11: No | CG11: No | CH11: Yes | CI11: Yes | CJ11: Yes | CK11: Yes | CL11: Yes | CM11: Yes | CN11: Yes | CO11: Yes | CP11: Yes | CQ11: No | CR11: No | CS11: No | CT11: No | CU11: No | CV11: No
A12: Sheridan College | B12: https://www.sheridancollege.ca | C12: 105 | D12: 78 | E12: 77 | F12: 77 | G12: =F12-E12 -> 0 | H12: =F12-D12 -> -1 | I12: 31 | J12: 105 | K12: 105 | L12: =K12-J12 -> 0 | M12: =K12-I12 -> 74 | N12: 110 | O12: 105 | P12: 105 | Q12: =P12-O12 -> 0 | R12: =P12-N12 -> -5 | S12: 87 | T12: 64 | U12: 64 | V12: =U12-T12 -> 0 | W12: =U12-S12 -> -23 | X12: 99 | Y12: 76 | Z12: 76 | AA12: =Z12-Y12 -> 0 | AB12: =Z12-X12 -> -23 | AC12: 100 | AD12: 73 | AE12: 73 | AF12: =AE12-AD12 -> 0 | AG12: =AE12-AC12 -> -27 | AH12: 100 | AI12: 73 | AJ12: 73 | AK12: =AJ12-AI12 -> 0 | AL12: =AJ12-AH12 -> -27 | AM12: 114 | AN12: 105 | AO12: 105 | AP12: =AO12-AN12 -> 0 | AQ12: =AO12-AM12 -> -9 | AR12: 0 | AS12: 4 | AT12: 4 | AU12: =AT12-AS12 -> 0 | AV12: =AT12-AR12 -> 4 | AW12: 72 | AX12: 72 | AY12: 72 | AZ12: =AY12-AX12 -> 0 | BA12: =AY12-AW12 -> 0 | BB12: 0 | BC12: 0 | BD12: 0 | BE12: =BD12-BC12 -> 0 | BF12: =BD12-BB12 -> 0 | BG12: 1 | BH12: 1 | BI12: 1 | BJ12: =BI12-BH12 -> 0 | BK12: =BI12-BG12 -> 0 | BL12: 0 | BM12: 0 | BN12: 0 | BO12: =BN12-BM12 -> 0 | BP12: =BN12-BL12 -> 0 | BQ12: 0 | BR12: 0 | BS12: 0 | BT12: =BS12-BR12 -> 0 | BU12: =BS12-BQ12 -> 0 | BV12: Yes | BW12: Yes | BX12: Yes | BY12: No | BZ12: No | CA12: No | CB12: Yes | CC12: Yes | CD12: Yes | CE12: No | CF12: No | CG12: No | CH12: Yes | CI12: Yes | CJ12: Yes | CK12: Yes | CL12: Yes | CM12: Yes | CN12: Yes | CO12: Yes | CP12: Yes | CQ12: No | CR12: No | CS12: No | CT12: No | CU12: No | CV12: No
A13: Camosun College | B13: https://camosun.ca | C13: 91 | D13: 8 | E13: 91 | F13: 91 | G13: =F13-E13 -> 0 | H13: =F13-D13 -> 83 | I13: 8 | J13: 91 | K13: 91 | L13: =K13-J13 -> 0 | M13: =K13-I13 -> 83 | N13: 8 | O13: 90 | P13: 90 | Q13: =P13-O13 -> 0 | R13: =P13-N13 -> 82 | S13: 8 | T13: 85 | U13: 85 | V13: =U13-T13 -> 0 | W13: =U13-S13 -> 77 | X13: 7 | Y13: 90 | Z13: 90 | AA13: =Z13-Y13 -> 0 | AB13: =Z13-X13 -> 83 | AC13: 8 | AD13: 86 | AE13: 86 | AF13: =AE13-AD13 -> 0 | AG13: =AE13-AC13 -> 78 | AH13: 0 | AI13: 15 | AJ13: 15 | AK13: =AJ13-AI13 -> 0 | AL13: =AJ13-AH13 -> 15 | AM13: 8 | AN13: 91 | AO13: 91 | AP13: =AO13-AN13 -> 0 | AQ13: =AO13-AM13 -> 83 | AR13: 7 | AS13: 49 | AT13: 49 | AU13: =AT13-AS13 -> 0 | AV13: =AT13-AR13 -> 42 | AW13: 6 | AX13: 76 | AY13: 76 | AZ13: =AY13-AX13 -> 0 | BA13: =AY13-AW13 -> 70 | BB13: 0 | BC13: 0 | BD13: 0 | BE13: =BD13-BC13 -> 0 | BF13: =BD13-BB13 -> 0 | BG13: 8 | BH13: 12 | BI13: 12 | BJ13: =BI13-BH13 -> 0 | BK13: =BI13-BG13 -> 4 | BL13: 0 | BM13: 0 | BN13: 0 | BO13: =BN13-BM13 -> 0 | BP13: =BN13-BL13 -> 0 | BQ13: 0 | BR13: 0 | BS13: 0 | BT13: =BS13-BR13 -> 0 | BU13: =BS13-BQ13 -> 0 | BV13: Yes | BW13: Yes | BX13: Yes | BY13: Yes | BZ13: Yes | CA13: Yes | CB13: Yes | CC13: Yes | CD13: Yes | CE13: No | CF13: No | CG13: No | CH13: Yes | CI13: Yes | CJ13: Yes | CK13: Yes | CL13: Yes | CM13: Yes | CN13: Yes | CO13: Yes | CP13: Yes | CQ13: No | CR13: No | CS13: No | CT13: No | CU13: No | CV13: No
A14: University of Manitoba | B14: https://umanitoba.ca | C14: 87 | D14: 4 | E14: 2 | F14: 2 | G14: =F14-E14 -> 0 | H14: =F14-D14 -> -2 | I14: 86 | J14: 87 | K14: 87 | L14: =K14-J14 -> 0 | M14: =K14-I14 -> 1 | N14: 140 | O14: 87 | P14: 87 | Q14: =P14-O14 -> 0 | R14: =P14-N14 -> -53 | S14: 20 | T14: 0 | U14: 0 | V14: =U14-T14 -> 0 | W14: =U14-S14 -> -20 | X14: 24 | Y14: 0 | Z14: 0 | AA14: =Z14-Y14 -> 0 | AB14: =Z14-X14 -> -24 | AC14: 51 | AD14: 0 | AE14: 0 | AF14: =AE14-AD14 -> 0 | AG14: =AE14-AC14 -> -51 | AH14: 0 | AI14: 0 | AJ14: 0 | AK14: =AJ14-AI14 -> 0 | AL14: =AJ14-AH14 -> 0 | AM14: 141 | AN14: 87 | AO14: 87 | AP14: =AO14-AN14 -> 0 | AQ14: =AO14-AM14 -> -54 | AR14: 0 | AS14: 0 | AT14: 0 | AU14: =AT14-AS14 -> 0 | AV14: =AT14-AR14 -> 0 | AW14: 1 | AX14: 0 | AY14: 0 | AZ14: =AY14-AX14 -> 0 | BA14: =AY14-AW14 -> -1 | BB14: 0 | BC14: 0 | BD14: 0 | BE14: =BD14-BC14 -> 0 | BF14: =BD14-BB14 -> 0 | BG14: 0 | BH14: 26 | BI14: 26 | BJ14: =BI14-BH14 -> 0 | BK14: =BI14-BG14 -> 26 | BL14: 0 | BM14: 0 | BN14: 0 | BO14: =BN14-BM14 -> 0 | BP14: =BN14-BL14 -> 0 | BQ14: 0 | BR14: 0 | BS14: 0 | BT14: =BS14-BR14 -> 0 | BU14: =BS14-BQ14 -> 0 | BV14: Yes | BW14: Yes | BX14: Yes | BY14: No | BZ14: No | CA14: No | CB14: Yes | CC14: Yes | CD14: Yes | CE14: No | CF14: No | CG14: No | CH14: Yes | CI14: Yes | CJ14: Yes | CK14: Yes | CL14: Yes | CM14: Yes | CN14: Yes | CO14: Yes | CP14: Yes | CQ14: Yes | CR14: Yes | CS14: Yes | CT14: No | CU14: No | CV14: No
... A54: Olds College | B54: https://www.oldscollege.ca | C54: 1 | D54: 0 | E54: 0 | F54: 0 | G54: =F54-E54 -> 0 | H54: =F54-D54 -> 0 | I54: 1 | J54: 1 | K54: 1 | L54: =K54-J54 -> 0 | M54: =K54-I54 -> 0 | N54: 1 | O54: 1 | P54: 1 | Q54: =P54-O54 -> 0 | R54: =P54-N54 -> 0 | S54: 0 | T54: 0 | U54: 0 | V54: =U54-T54 -> 0 | W54: =U54-S54 -> 0 | X54: 0 | Y54: 0 | Z54: 0 | AA54: =Z54-Y54 -> 0 | AB54: =Z54-X54 -> 0 | AC54: 0 | AD54: 0 | AE54: 0 | AF54: =AE54-AD54 -> 0 | AG54: =AE54-AC54 -> 0 | AH54: 0 | AI54: 0 | AJ54: 0 | AK54: =AJ54-AI54 -> 0 | AL54: =AJ54-AH54 -> 0 | AM54: 1 | AN54: 1 | AO54: 1 | AP54: =AO54-AN54 -> 0 | AQ54: =AO54-AM54 -> 0 | AR54: 0 | AS54: 1 | AT54: 1 | AU54: =AT54-AS54 -> 0 | AV54: =AT54-AR54 -> 1 | AW54: 0 | AX54: 0 | AY54: 0 | AZ54: =AY54-AX54 -> 0 | BA54: =AY54-AW54 -> 0 | BB54: 0 | BC54: 0 | BD54: 0 | BE54: =BD54-BC54 -> 0 | BF54: =BD54-BB54 -> 0 | BG54: 0 | BH54: 0 | BI54: 0 | BJ54: =BI54-BH54 -> 0 | BK54: =BI54-BG54 -> 0 | BL54: 0 | BM54: 0 | BN54: 0 | BO54: =BN54-BM54 -> 0 | BP54: =BN54-BL54 -> 0 | BQ54: 0 | BR54: 0 | BS54: 0 | BT54: =BS54-BR54 -> 0 | BU54: =BS54-BQ54 -> 0 | BV54: Yes | BW54: Yes | BX54: Yes | BY54: No | BZ54: No | CA54: No | CB54: No | CC54: No | CD54: No | CE54: No | CF54: No | CG54: No | CH54: Yes | CI54: Yes | CJ54: Yes | CK54: Yes | CL54: Yes | CM54: Yes | CN54: Yes | CO54: Yes | CP54: Yes | CQ54: No | CR54: No | CS54: No | CT54: No | CU54: No | CV54: No

Sheet Long list
A1: Provider | B1: Website | C1: Courses | D1: Level | E1: Field | F1: Start | G1: Previous | H1: Today | I1: Change today | J1: Change since start
A2: University of British Columbia (UBC) | B2: https://www.ubc.ca | C2: 575 | D2: Course | E2: Official course page | F2: 342 | G2: 343 | H2: 343 | I2: =H2-G2 -> 0 | J2: =H2-F2 -> 1
A3: University of British Columbia (UBC) | B3: https://www.ubc.ca | C3: 575 | D3: Course | E3: Study level | F3: 575 | G3: 575 | H3: 575 | I3: =H3-G3 -> 0 | J3: =H3-F3 -> 0
A4: University of British Columbia (UBC) | B4: https://www.ubc.ca | C4: 575 | D4: Course | E4: Field of study | F4: 569 | G4: 570 | H4: 570 | I4: =H4-G4 -> 0 | J4: =H4-F4 -> 1
A5: University of British Columbia (UBC) | B5: https://www.ubc.ca | C5: 575 | D5: Course | E5: Duration | F5: 270 | G5: 189 | H5: 189 | I5: =H5-G5 -> 0 | J5: =H5-F5 -> -81
A6: University of British Columbia (UBC) | B6: https://www.ubc.ca | C6: 575 | D6: Course | E6: Delivery mode | F6: 441 | G6: 316 | H6: 316 | I6: =H6-G6 -> 0 | J6: =H6-F6 -> -125
A7: University of British Columbia (UBC) | B7: https://www.ubc.ca | C7: 575 | D7: Course | E7: Campus linked | F7: 465 | G7: 314 | H7: 314 | I7: =H7-G7 -> 0 | J7: =H7-F7 -> -151
A8: University of British Columbia (UBC) | B8: https://www.ubc.ca | C8: 575 | D8: Course | E8: Campus city | F8: 465 | G8: 314 | H8: 314 | I8: =H8-G8 -> 0 | J8: =H8-F8 -> -151
A9: University of British Columbia (UBC) | B9: https://www.ubc.ca | C9: 575 | D9: Course | E9: Open to international students | F9: 575 | G9: 575 | H9: 575 | I9: =H9-G9 -> 0 | J9: =H9-F9 -> 0
A10: University of British Columbia (UBC) | B10: https://www.ubc.ca | C10: 575 | D10: Course | E10: Tuition fee | F10: 275 | G10: 275 | H10: 275 | I10: =H10-G10 -> 0 | J10: =H10-F10 -> 0
A11: University of British Columbia (UBC) | B11: https://www.ubc.ca | C11: 575 | D11: Course | E11: Intakes / start dates | F11: 250 | G11: 252 | H11: 252 | I11: =H11-G11 -> 0 | J11: =H11-F11 -> 2
A12: University of British Columbia (UBC) | B12: https://www.ubc.ca | C12: 575 | D12: Course | E12: Application deadline | F12: 0 | G12: 0 | H12: 0 | I12: =H12-G12 -> 0 | J12: =H12-F12 -> 0
A13: University of British Columbia (UBC) | B13: https://www.ubc.ca | C13: 575 | D13: Course | E13: English requirements | F13: 539 | G13: 539 | H13: 539 | I13: =H13-G13 -> 0 | J13: =H13-F13 -> 0
... A1197: Olds College | B1197: https://www.oldscollege.ca | C1197: 1 | D1197: Provider (1 = held) | E1197: Description | F1197: 0 | G1197: 0 | H1197: 0 | I1197: =H1197-G1197 -> 0 | J1197: =H1197-F1197 -> 0

Sheet Courses
A1: Provider | B1: Course | C1: Course code | D1: Official course page | E1: Study level | F1: Field of study | G1: Duration | H1: Delivery mode | I1: Campuses | J1: Campus city | K1: Open to international students | L1: Open to domestic students | M1: Tuition fee | N1: Registered tuition (CRICOS) | O1: Intakes / start dates | P1: Application deadline | Q1: English requirements | R1: Academic entry requirements | S1: Entry requirements (course) | T1: Course description | U1: Provider scholarships (active)
A2: Alberta University of the Arts | B2: Bachelor of Design Photography | C2: f03df216-113c-415f-83d2-a12700c5f323 | D2: — course page not found yet | E2: Bachelor | F2: Visual Arts and Crafts | G2: — not on the course page | H2: — not on the course page | I2: — not on the course page | J2: — not on the course page | K2: Yes | M2: — course page not found yet | O2: — course page not found yet | P2: — no reader yet | Q2: — course page not found yet | R2: — no reader yet | T2: — no reader yet | U2: 0
A3: Alberta University of the Arts | B3: Bachelor of Design Visual Communications Design | C3: 36f2c622-a01c-4a9e-a53f-a12700c5f323 | D3: — course page not found yet | E3: Bachelor | F3: Graphic and Design Studies | G3: — not on the course page | H3: — not on the course page | I3: — not on the course page | J3: — not on the course page | K3: Yes | M3: — course page not found yet | O3: — course page not found yet | P3: — no reader yet | Q3: — course page not found yet | R3: — no reader yet | T3: — no reader yet | U3: 0
A4: Alberta University of the Arts | B4: Bachelor of Fine Arts First Year Studies | C4: 20b768c6-b0ac-431a-ac19-a12700c5f323 | D4: — course page not found yet | E4: Bachelor | F4: Visual Arts and Crafts | G4: — not on the course page | H4: — not on the course page | I4: — not on the course page | J4: — not on the course page | K4: Yes | M4: — course page not found yet | O4: — course page not found yet | P4: — no reader yet | Q4: — course page not found yet | R4: — no reader yet | T4: — no reader yet | U4: 0
A5: Alberta University of the Arts | B5: Bachelor of Fine Arts Studio Art | C5: 1441180c-3a61-44b3-a50b-9322b7f62a4d | D5: — course page not found yet | E5: Bachelor | F5: Visual Arts and Crafts | G5: — not on the course page | H5: — not on the course page | I5: — not on the course page | J5: — not on the course page | K5: Yes | M5: — course page not found yet | O5: — course page not found yet | P5: — no reader yet | Q5: — course page not found yet | R5: — no reader yet | T5: — no reader yet | U5: 0
A6: Alberta University of the Arts | B6: Master of Fine Arts in Craft Media Craft Media | C6: 3569201c-5ff0-4031-9e2c-a3c5d9d92252 | D6: — course page not found yet | E6: Masters | F6: Visual Arts and Crafts | G6: — not on the course page | H6: — not on the course page | I6: — not on the course page | J6: — not on the course page | K6: Yes | M6: — course page not found yet | O6: — course page not found yet | P6: — no reader yet | Q6: — course page not found yet | R6: — no reader yet | T6: — no reader yet | U6: 0
A7: Algonquin College | B7: Accounting | C7: 6000X07PAO | D7: https://www.algonquincollege.com/business-hospitality/program/accounting-and-financial-practice/ | E7: Graduate Certificate | F7: Accounting | G7: 1 years | H7: blended | I7: Ottawa (blended) | J7: Ottawa | K7: Yes | M7: — page found, not read yet | O7: — page found, not read yet | P7: — no reader yet | Q7: IELTS 7 {"reading": 6, "writing": 6, "speaking": 6, "listening": 6} | TOEFL_IBT 88 | R7: — no reader yet | T7: — no reader yet | U7: 0
A8: Algonquin College | B8: Addictions and Mental Health | C8: 1829X07PAO | D8: https://www.algonquincollege.com/online/program-info/addictions-and-mental-health/ | E8: Graduate Certificate | F8: Human Welfare Studies and Services | G8: — not on the course page | H8: online | I8: — not on the course page | J8: — not on the course page | K8: Yes | M8: — page found, not read yet | O8: — page found, not read yet | P8: — no reader yet | Q8: IELTS 7 {"reading": 6, "writing": 6, "speaking": 6, "listening": 6} | R8: — no reader yet | T8: — no reader yet | U8: 0
A9: Algonquin College | B9: Addictions and Mental Health | C9: 1829X09FAO | D9: https://www.algonquincollege.com/online/program-info/addictions-and-mental-health/ | E9: Graduate Certificate | F9: Other Health | G9: — not on the course page | H9: online | I9: — in review | J9: — in review | K9: Yes | M9: — page found, not read yet | O9: — page found, not read yet | P9: — no reader yet | Q9: IELTS 7 {"reading": 6, "writing": 6, "speaking": 6, "listening": 6} | R9: — no reader yet | T9: — no reader yet | U9: 0
A10: Algonquin College | B10: Autism and Behavioural Science | C10: 3017X09FAO | D10: https://www.algonquincollege.com/online/program-info/autism-and-behavioural-science/ | E10: Graduate Certificate | F10: Behavioural Science | G10: — not on the course page | H10: online | I10: — in review | J10: — in review | K10: Yes | M10: — page found, not read yet | O10: — page found, not read yet | P10: — no reader yet | Q10: IELTS 7 {"reading": 6, "writing": 6, "speaking": 6, "listening": 6} | R10: — no reader yet | T10: — no reader yet | U10: 0
A11: Algonquin College | B11: Autism and Behavioural Science | C11: 3017X07PAO | D11: https://www.algonquincollege.com/online/program-info/autism-and-behavioural-science/ | E11: Graduate Certificate | F11: Behavioural Science | G11: — not on the course page | H11: online | I11: — not on the course page | J11: — not on the course page | K11: Yes | M11: — page found, not read yet | O11: — page found, not read yet | P11: — no reader yet | Q11: IELTS 7 {"reading": 6, "writing": 6, "speaking": 6, "listening": 6} | R11: — no reader yet | T11: — no reader yet | U11: 0
A12: Algonquin College | B12: Bachelor of Business Administration (Trades Management) (Honours) – Pathway for Building Renovation Technology | C12: 6800A03PAO | D12: — course page not found yet | E12: Bachelor Honours Degree | F12: Business and Management | G12: — not on the course page | H12: online | I12: Ottawa (on_campus) | J12: Ottawa | K12: Yes | M12: — course page not found yet | O12: — course page not found yet | P12: — no reader yet | Q12: — course page not found yet | R12: — no reader yet | T12: — no reader yet | U12: 0
A13: Algonquin College | B13: Bachelor of Business Administration (Trades Management) (Honours) – Pathway for Business – Trades | C13: 6800B03PAO | D13: — course page not found yet | E13: Bachelor Honours Degree | F13: Business and Management | G13: — not on the course page | H13: online | I13: Ottawa (on_campus) | J13: Ottawa | K13: Yes | M13: — course page not found yet | O13: — course page not found yet | P13: — no reader yet | Q13: — course page not found yet | R13: — no reader yet | T13: — no reader yet | U13: 0
... A3815: Yukon University | B3815: Education Degree (YNTEP) - Yukon Native Teacher Education Program | C3815: 92 | D3815: https://www.yukonu.ca/programs/yukon-native-teacher-education-program-degree | E3815: Bachelor | F3815: Teacher Education | G3815: — not on the course page | H3815: blended | I3815: Whitehorse (Ayamdigut) (blended) | J3815: Whitehorse | K3815: Yes | M3815: — page found, not read yet | O3815: — page found, not read yet | P3815: — no reader yet | Q3815: — page found, not read yet | R3815: — no reader yet | T3815: — no reader yet | U3815: 1

Sheet Entry requirements
A1: Provider | B1: Kind | C1: Status | D1: Level | E1: Study level | F1: Applicant country | G1: Qualification | H1: Benchmark band | I1: Minimum grade | J1: Minimum value | K1: Grade scale | L1: Audience | M1: Intake year | N1: Edition | O1: Quote | P1: Source page | Q1: As at

Sheet Scholarships
A1: Provider | B1: Scholarship | C1: Type | D1: Audience | E1: Award (as written) | F1: Award type | G1: Amount | H1: Currency | I1: Percentage | J1: Up to (maximum) | K1: Applies to fee | L1: Fee basis | M1: Duration basis | N1: Application required | O1: Applications open | P1: Applications close | Q1: Academic year | R1: Study start | S1: Nationalities | T1: Description | U1: Source page | V1: Publication status
A2: Burman University | B2: Burman University Orchestral Scholarship | C2: provider_scholarship | D2: international_and_domestic | E2: Award: $8,000 | F2: fixed_amount | G2: 8000 | H2: CAD | J2: No | P2: 2023-07-01 | U2: https://www.burmanu.ca/orchestralscholarship | V2: published
A3: Burman University | B3: Scholarships - Nursing | C3: provider_scholarship | D3: not_stated | F3: text_only | J3: No | U3: https://www.burmanu.ca/studentfinancialservices/scholarship/nursing | V3: unpublished
A4: Capilano University | B4: Athletic Entrance Award | C4: provider_scholarship | D4: international | F4: text_only | J4: No | U4: https://ssb9s.capilanou.ca:8443/BcFinaidSelfService/ssb/awardGuide#!/welcome/0369/awardDetails | V4: unpublished
A5: Capilano University | B5: International Entrance & Performance Award (IEPA) | C5: provider_scholarship | D5: international | F5: text_only | J5: No | M5: per_semester | U5: https://www.capilanou.ca/admissions/fees--finances/financial-aid--awards/funding-for-international-students/ | V5: unpublished
A6: Kwantlen Polytechnic University | B6: Huayu B.E.S.T. Scholarship - Shih Chien University (Taiwan) | C6: provider_scholarship | D6: international | E6: The scholarship is in the form of a monthly stipend of NT$28,000 (approx. CAD$1,200). | F6: fixed_amount | G6: 28000 | H6: CAD | J6: No | U6: https://www.kpu.ca/study-abroad-scholarship/huayu-best-scholarship | V6: published
A7: Kwantlen Polytechnic University | B7: KPU International Study Abroad Scholarship | C7: provider_scholarship | D7: international_and_domestic | E7: Amount: Up to $3000 (per recipient) | F7: fixed_amount | G7: 3000 | H7: CAD | J7: No | U7: https://www.kpu.ca/studyabroad/go-on-exchange/funding-scholarships/internal-awards | V7: published
A8: Kwantlen Polytechnic University | B8: KPU International's Food Relief Grant | C8: provider_scholarship | D8: international | E8: offering up to $250 to assist students experiencing food insecurity | F8: fixed_amount | G8: 250 | H8: CAD | J8: No | U8: https://www.kpu.ca/KPU-International-Food-Relief-Grant | V8: published
A9: Royal Roads University | B9: A.C.T. (Access. Courage. Transformation) Award | C9: provider_scholarship | D9: international | F9: text_only | J9: No | U9: https://www.royalroads.ca/act-award | V9: unpublished
A10: Royal Roads University | B10: Chia-Fu Tsai Scholarship | C10: provider_scholarship | D10: international | E10: The award is valued up to $3,500 at the discretion of RRU's Awards Adjudication Panel. | F10: fixed_amount | G10: 3500 | H10: CAD | J10: No | M10: annual | S10: TW | U10: https://www.royalroads.ca/chia-fu-tsai-scholarship | V10: published
A11: Royal Roads University | B11: Dr. Martha Farrell International Scholarship for Global Leaders | C11: provider_scholarship | D11: international | F11: text_only | J11: No | O11: 2020-01-01 | U11: https://www.royalroads.ca/dr-martha-farrell-international-scholarship-global-leaders | V11: unpublished
A12: Royal Roads University | B12: Royal Roads Scholarship for Outstanding Children of International Alumni | C12: provider_scholarship | D12: international | E12: Ten awards of $2,000 will be open for competition each year to entering undergraduate students who prove the potential for academic excellence in the Canadian educational syst | F12: fixed_amount | G12: 2000 | H12: CAD | J12: No | U12: https://royalroads.ca/royal-roads-scholarship-outstanding-children-international-alumni | V12: published
A13: Royal Roads University | B13: Royal Roads University Student Association (RRUSA) Bursary | C13: provider_scholarship | D13: international_and_domestic | F13: text_only | J13: No | U13: https://www.royalroads.ca/royal-roads-university-student-association-rrusa-bursary | V13: unpublished
A14: Royal Roads University | B14: RRU Royal Scholarship | C14: provider_scholarship | D14: international | F14: text_only | J14: No | O14: 2023-09-01 | P14: 2023-11-01 | S14: CN | U14: https://www.royalroads.ca/rru-royal-scholarship | V14: unpublished
A15: Royal Roads University | B15: Shu-Hui Kuo Scholarship | C15: provider_scholarship | D15: international | E15: The award is valued up to $3,500 at the discretion of RRU's Awards Adjudication Panel | F15: fixed_amount | G15: 3500 | H15: CAD | J15: No | M15: annual | P15: 2025-11-01 | S15: TW | U15: https://www.royalroads.ca/shu-hui-kuo-scholarship | V15: published
A16: Royal Roads University | B16: The Dr. Martha Farrell International Scholarship for Global Leaders | C16: provider_scholarship | D16: international | F16: text_only | J16: No | U16: https://www.royalroads.ca/dr-martha-farrell-international-scholarship-global-leaders-0 | V16: unpublished
A17: Royal Roads University | B17: UAS7 Travel Scholarship | C17: provider_scholarship | D17: international_and_domestic | F17: text_only | J17: No | U17: https://www.royalroads.ca/uas7-travel-scholarship | V17: unpublished
A18: Royal Roads University | B18: UMAP-Canada Scholarship | C18: provider_scholarship | D18: international_and_domestic | F18: text_only | J18: No | O18: 2025-04-01 | P18: 2026-03-31 | R18: 2025 | U18: https://www.royalroads.ca/umap-canada-scholarship | V18: unpublished
A19: Simon Fraser University (SFU) | B19: Canada Graduate Research Scholarship - Doctoral (CGRS D) | C19: provider_scholarship | D19: international_and_domestic | E19: Award Value: $40,000/yr for 3 years | F19: fixed_amount | G19: 40000 | H19: CAD | J19: No | M19: program_duration | P19: 2026-10-01 | U19: https://www.sfu.ca/gradstudies/awards-funding/external-gov-funded/cgrsd.html | V19: published
A20: Simon Fraser University (SFU) | B20: China Scholarship Council (CSC) Scholarship (PhD) | C20: provider_scholarship | D20: international | F20: text_only | J20: No | S20: CN | U20: https://www.sfu.ca/gradstudies/awards-funding/external-gov-funded/csc.html | V20: unpublished
A21: Simon Fraser University (SFU) | B21: Undergraduate Scholars Entrance Scholarship | C21: provider_scholarship | D21: international_and_domestic | F21: text_only | J21: No | O21: 2026-10-01 | P21: 2026-12-15 | U21: https://www.sfu.ca/students/admission/fees-scholarships/uses.html | V21: unpublished
A22: Thompson Rivers University | B22: Engineering Scholarships | C22: provider_scholarship | D22: international | E22: Two new international students per year will be selected to receive a $3,000 scholarship each divided over four semesters ($1,000 first year and $2,000 second year) | F22: fixed_amount | G22: 3000 | H22: CAD | J22: No | U22: https://www.tru.ca/truworld/future-students/scholarships/engineering-scholarships.html | V22: published
A23: Thompson Rivers University | B23: The Jorge Campos Award for Studies in Canada TRU WORLD | C23: provider_scholarship | D23: not_stated | F23: text_only | J23: No | M23: annual | U23: https://www.tru.ca/truworld/future-students/scholarships/jorge-campos-award.html | V23: unpublished
A24: Thompson Rivers University | B24: TRU International Social Media Ambassador Award | C24: provider_scholarship | D24: international | F24: text_only | J24: No | U24: https://www.tru.ca/truworld/future-students/scholarships/social-media-ambassadors.html | V24: unpublished
A25: Thompson Rivers University | B25: Vantage Airport Group International Award | C25: provider_scholarship | D25: international | E25: will automatically be considered to receive a $7500 award | F25: fixed_amount | G25: 7500 | H25: CAD | J25: No | U25: https://www.tru.ca/truworld/future-students/scholarships/scholarships-for-residents-of-bahamas-and-caribbean.html | V25: published
A26: University of British Columbia (UBC) | B26: ANID Becas Chile Scholarship | C26: provider_scholarship | D26: international | E26: The award includes full tuition fees, stipend, airfare, and health insurance. | F26: percentage | I26: 100 | J26: No | K26: tuition_fee | U26: https://lled.educ.ubc.ca/congratulations-to-aracely-aguilera-on-being-awarded-the-becas-chile-scholarship/ | V26: published
A27: University of British Columbia (UBC) | B27: Arthritis Society Graduate PhD Salary Award | C27: provider_scholarship | D27: international_and_domestic | E27: The program provides 50% of the salary award to successful applicants. | F27: percentage | I27: 50 | J27: No | K27: tuition_fee | P27: 2027-04-30 | U27: https://www.grad.ubc.ca/awards/arthritis-society-graduate-phd-salary-award | V27: published
A28: University of British Columbia (UBC) | B28: Elizabeth Henry Scholarship for Communities and Environmental Health | C28: provider_scholarship | D28: international_and_domestic | E28: Value $4,000 | F28: fixed_amount | G28: 4000 | H28: CAD | J28: No | P28: 2027-05-31 | U28: https://www.grad.ubc.ca/awards/elizabeth-henry-scholarship-communities-environmental-health | V28: published
A29: University of British Columbia (UBC) | B29: Friedman Award for Scholars in Health | C29: provider_scholarship | D29: international_and_domestic | E29: Awards of up to $50,000 each will be granted for 6 to 12 months of study | F29: fixed_amount | G29: 50000 | H29: CAD | J29: No | P29: 2026-03-06 | U29: https://www.grad.ubc.ca/awards/friedman-award-scholars-health | V29: published
A30: University of British Columbia (UBC) | B30: Global Scholarship Programme for Research Excellence | C30: provider_scholarship | D30: international_and_domestic | F30: text_only | J30: No | U30: https://www.grad.ubc.ca/awards/global-scholarship-programme-research-excellence-0 | V30: unpublished
A31: University of British Columbia (UBC) | B31: Google Lime Scholarship | C31: provider_scholarship | D31: international_and_domestic | F31: text_only | J31: No | P31: 2026-12-31 | U31: https://www.grad.ubc.ca/awards/google-lime-scholarship | V31: unpublished
A32: University of British Columbia (UBC) | B32: IDRC Doctoral Research Awards | C32: provider_scholarship | D32: international_and_domestic | E32: Value up to $20,000 | F32: fixed_amount | G32: 20000 | H32: CAD | J32: No | U32: https://www.grad.ubc.ca/awards/idrc-doctoral-research-awards | V32: published
A33: University of British Columbia (UBC) | B33: International Four-Year Doctoral Partial Tuition Award | C33: provider_scholarship | D33: international | E33: Value: Difference between international and domestic tuition (approximately $4,343) Duration: Up to 48 months of study Eligibility Awardees must hold a valid student visa and be registered full time when they begin their UBCO PhD program | F33: fixed_amount | G33: 4343 | H33: CAD | J33: No | U33: https://gradstudies.ok.ubc.ca/resources/award-opportunities/idpt/ | V33: published
A34: University of British Columbia (UBC) | B34: International Tuition Award | C34: provider_scholarship | D34: international | E34: Up to C$3,200 | F34: fixed_amount | G34: 3200 | H34: CAD | J34: Yes | M34: annual | P34: 2026-12-31 | U34: https://www.grad.ubc.ca/awards/international-tuition-award | V34: published
A35: University of British Columbia (UBC) | B35: Killam Doctoral Scholarships | C35: provider_scholarship | D35: international_and_domestic | E35: At present, the Killam Doctoral Scholarship provides an annual stipend valued at $40,000 for two years* | F35: fixed_amount | G35: 40000 | H35: CAD | J35: No | M35: annual_program_duration | U35: https://www.grad.ubc.ca/awards/killam-doctoral-scholarships | V35: published
A36: University of British Columbia (UBC) | B36: Mitacs Globalink Research Award | C36: provider_scholarship | D36: international_and_domestic | E36: The award provides $6,000 for senior undergraduate and graduate students to undertake 12- to 24-week research projects supervised by professors at accredited universities overseas. | F36: fixed_amount | G36: 6000 | H36: CAD | J36: No | P36: 2025-05-19 | U36: https://www.grad.ubc.ca/awards/mitacs-globalink-research-award | V36: published
A37: University of British Columbia (UBC) | B37: President's Academic Excellence Initiative PhD Award | C37: provider_scholarship | D37: international_and_domestic | E37: er year for domestic part-time students (years 1 to 5) ($310/term) $1,260 per year for domestic students being assessed full tuition fees (years 1 to 3), domestic MDPHD students (years 1 to 6), and domestic MPTPHD students (years 1 to 2) ($420/term) $1,500 per year for internatio | F37: percentage | I37: 100 | J37: No | K37: tuition_fee | P37: 2026-12-31 | U37: https://www.grad.ubc.ca/awards/presidents-academic-excellence-initiative-phd-award | V37: published
A38: University of British Columbia (UBC) | B38: Research Student Scholarship | C38: provider_scholarship | D38: international | E38: The scholarship covers full tuition, a monthly allowance and a round-trip flight between Canada and Japan | F38: percentage | I38: 100 | J38: No | K38: tuition_fee | P38: 2017-05-19 | R38: October 2018 | U38: https://sppga.ubc.ca/opportunities/mext-scholarship-programs/ | V38: published
A39: University of British Columbia (UBC) | B39: Sauder School of Business International Student Scholarship (#1014) | C39: provider_scholarship | D39: international | F39: text_only | J39: No | U39: https://mybcom.sauder.ubc.ca/courses-money-and-enrolment/scholarships/sauder-school-business-international-student-scholarship | V39: unpublished
A40: University of British Columbia (UBC) | B40: Simons Award in Nuclear Disarmament and Global Security | C40: provider_scholarship | D40: international_and_domestic | F40: text_only | J40: No | U40: https://www.grad.ubc.ca/awards/simons-award-nuclear-disarmament-global-security | V40: unpublished
...

Sheet Toolset use
A1: Toolset use by Canada providers: 2026-10-31 and the 7 days to it
A3: Tool | B3: Used (day) | C3: Worked (day) | D3: Did not work (day) | E3: Credits (day) | F3: AI US$ (day) | G3: Used (7 days) | H3: Worked (7 days) | I3: Did not work (7 days) | J3: Credits (7 days) | K3: AI US$ (7 days) | L3: Worked share (7 days)
A4: Course-page search | B4: =SUMIF($B$15:$B$189,$A4,C$15:C$189) -> 0 | C4: =SUMIF($B$15:$B$189,$A4,D$15:D$189) -> 0 | D4: =SUMIF($B$15:$B$189,$A4,E$15:E$189) -> 0 | E4: =SUMIF($B$15:$B$189,$A4,F$15:F$189) -> 0 | F4: =SUMIF($B$15:$B$189,$A4,G$15:G$189) -> 0 | G4: =SUMIF($B$15:$B$189,$A4,H$15:H$189) -> 134 | H4: =SUMIF($B$15:$B$189,$A4,I$15:I$189) -> 0 | I4: =SUMIF($B$15:$B$189,$A4,J$15:J$189) -> 62 | ... K4: =SUMIF($B$15:$B$189,$A4,L$15:L$189) -> 0 | L4: =IF(G4=0,"",H4/G4) -> 0
A5: Course page reads | B5: =SUMIF($B$15:$B$189,$A5,C$15:C$189) -> 13 | C5: =SUMIF($B$15:$B$189,$A5,D$15:D$189) -> 0 | D5: =SUMIF($B$15:$B$189,$A5,E$15:E$189) -> 0 | E5: =SUMIF($B$15:$B$189,$A5,F$15:F$189) -> 13 | F5: =SUMIF($B$15:$B$189,$A5,G$15:G$189) -> 0 | G5: =SUMIF($B$15:$B$189,$A5,H$15:H$189) -> 224 | H5: =SUMIF($B$15:$B$189,$A5,I$15:I$189) -> 8 | I5: =SUMIF($B$15:$B$189,$A5,J$15:J$189) -> 4 | ... K5: =SUMIF($B$15:$B$189,$A5,L$15:L$189) -> 0 | L5: =IF(G5=0,"",H5/G5) -> 0.035714286
A6: AI page match | B6: =SUMIF($B$15:$B$189,$A6,C$15:C$189) -> 41 | C6: =SUMIF($B$15:$B$189,$A6,D$15:D$189) -> 0 | D6: =SUMIF($B$15:$B$189,$A6,E$15:E$189) -> 28 | E6: =SUMIF($B$15:$B$189,$A6,F$15:F$189) -> 0 | F6: =SUMIF($B$15:$B$189,$A6,G$15:G$189) -> 0.00467406 | G6: =SUMIF($B$15:$B$189,$A6,H$15:H$189) -> 843 | H6: =SUMIF($B$15:$B$189,$A6,I$15:I$189) -> 1 | I6: =SUMIF($B$15:$B$189,$A6,J$15:J$189) -> 695 | ... K6: =SUMIF($B$15:$B$189,$A6,L$15:L$189) -> 0.11043069 | L6: =IF(G6=0,"",H6/G6) -> 0.0011862396
A7: AI field reader | B7: =SUMIF($B$15:$B$189,$A7,C$15:C$189) -> 27 | C7: =SUMIF($B$15:$B$189,$A7,D$15:D$189) -> 3 | D7: =SUMIF($B$15:$B$189,$A7,E$15:E$189) -> 24 | E7: =SUMIF($B$15:$B$189,$A7,F$15:F$189) -> 0 | F7: =SUMIF($B$15:$B$189,$A7,G$15:G$189) -> 0.0019136 | G7: =SUMIF($B$15:$B$189,$A7,H$15:H$189) -> 671 | H7: =SUMIF($B$15:$B$189,$A7,I$15:I$189) -> 29 | I7: =SUMIF($B$15:$B$189,$A7,J$15:J$189) -> 642 | ... K7: =SUMIF($B$15:$B$189,$A7,L$15:L$189) -> 0.0440996 | L7: =IF(G7=0,"",H7/G7) -> 0.043219076
A8: Fee reader (AI) | B8: =SUMIF($B$15:$B$189,$A8,C$15:C$189) -> 0 | C8: =SUMIF($B$15:$B$189,$A8,D$15:D$189) -> 0 | D8: =SUMIF($B$15:$B$189,$A8,E$15:E$189) -> 0 | E8: =SUMIF($B$15:$B$189,$A8,F$15:F$189) -> 0 | F8: =SUMIF($B$15:$B$189,$A8,G$15:G$189) -> 0 | G8: =SUMIF($B$15:$B$189,$A8,H$15:H$189) -> 184 | H8: =SUMIF($B$15:$B$189,$A8,I$15:I$189) -> 65 | I8: =SUMIF($B$15:$B$189,$A8,J$15:J$189) -> 119 | ... K8: =SUMIF($B$15:$B$189,$A8,L$15:L$189) -> 0.4637132 | L8: =IF(G8=0,"",H8/G8) -> 0.35326087
A9: Scholarship AI | B9: =SUMIF($B$15:$B$189,$A9,C$15:C$189) -> 0 | C9: =SUMIF($B$15:$B$189,$A9,D$15:D$189) -> 0 | D9: =SUMIF($B$15:$B$189,$A9,E$15:E$189) -> 0 | E9: =SUMIF($B$15:$B$189,$A9,F$15:F$189) -> 0 | F9: =SUMIF($B$15:$B$189,$A9,G$15:G$189) -> 0 | G9: =SUMIF($B$15:$B$189,$A9,H$15:H$189) -> 3 | H9: =SUMIF($B$15:$B$189,$A9,I$15:I$189) -> 3 | I9: =SUMIF($B$15:$B$189,$A9,J$15:J$189) -> 0 | ... K9: =SUMIF($B$15:$B$189,$A9,L$15:L$189) -> 0 | L9: =IF(G9=0,"",H9/G9) -> 1
A10: Other scraper credits | B10: =SUMIF($B$15:$B$189,$A10,C$15:C$189) -> 5 | C10: =SUMIF($B$15:$B$189,$A10,D$15:D$189) -> 0 | D10: =SUMIF($B$15:$B$189,$A10,E$15:E$189) -> 0 | E10: =SUMIF($B$15:$B$189,$A10,F$15:F$189) -> 5 | F10: =SUMIF($B$15:$B$189,$A10,G$15:G$189) -> 0 | G10: =SUMIF($B$15:$B$189,$A10,H$15:H$189) -> 222 | H10: =SUMIF($B$15:$B$189,$A10,I$15:I$189) -> 0 | I10: =SUMIF($B$15:$B$189,$A10,J$15:J$189) -> 0 | ... K10: =SUMIF($B$15:$B$189,$A10,L$15:L$189) -> 0 | L10: =IF(G10=0,"",H10/G10) -> 0
A11: Flags raised | B11: =SUMIF($B$15:$B$189,$A11,C$15:C$189) -> 0 | C11: =SUMIF($B$15:$B$189,$A11,D$15:D$189) -> 0 | D11: =SUMIF($B$15:$B$189,$A11,E$15:E$189) -> 0 | E11: =SUMIF($B$15:$B$189,$A11,F$15:F$189) -> 0 | F11: =SUMIF($B$15:$B$189,$A11,G$15:G$189) -> 0 | G11: =SUMIF($B$15:$B$189,$A11,H$15:H$189) -> 20 | H11: =SUMIF($B$15:$B$189,$A11,I$15:I$189) -> 0 | I11: =SUMIF($B$15:$B$189,$A11,J$15:J$189) -> 0 | ... K11: =SUMIF($B$15:$B$189,$A11,L$15:L$189) -> 0 | L11: =IF(G11=0,"",H11/G11) -> 0
A14: Provider | B14: Tool | C14: Used (day) | D14: Worked (day) | E14: Did not work (day) | F14: Credits (day) | G14: AI US$ (day) | H14: Used (7 days) | I14: Worked (7 days) | J14: Did not work (7 days) | K14: Credits (7 days) | L14: AI US$ (7 days) | M14: Worked share (7 days)
A15: Alberta University of the Arts | B15: Other scraper credits | C15: 0 | D15: 0 | E15: 0 | F15: 0 | G15: 0 | H15: 2 | I15: 0 | J15: 0 | K15: 2 | L15: 0 | M15: =IF(H15=0,"",I15/H15) -> 0
A16: Algonquin College | B16: Course page reads | C16: 1 | D16: 0 | E16: 0 | F16: 1 | G16: 0 | H16: 1 | I16: 0 | J16: 0 | K16: 1 | L16: 0 | M16: =IF(H16=0,"",I16/H16) -> 0
A17: Algonquin College | B17: AI page match | C17: 4 | D17: 0 | E17: 3 | F17: 0 | G17: 0.00058179 | H17: 4 | I17: 0 | J17: 3 | K17: 0 | L17: 0.00058179 | M17: =IF(H17=0,"",I17/H17) -> 0
A18: Algonquin College | B18: Fee reader (AI) | C18: 0 | D18: 0 | E18: 0 | F18: 0 | G18: 0 | H18: 6 | I18: 2 | J18: 4 | K18: 0 | L18: 0.023538 | M18: =IF(H18=0,"",I18/H18) -> 0.33333333
A19: Algonquin College | B19: Other scraper credits | C19: 0 | D19: 0 | E19: 0 | F19: 0 | G19: 0 | H19: 8 | I19: 0 | J19: 0 | K19: 15 | L19: 0 | M19: =IF(H19=0,"",I19/H19) -> 0
